Workbook

Sheet 민평표
O3: Web : | P3: www.kidb.com
O4: Date: | P4: =TODAY() -> 43712
A5: 전일민평(국고/통안/예보/국주/지역채)
B6: 종목명 | C6: 만기일 | D6: 요일 | E6: 민평 | F6: 전일비 | G6: 상장액(백만) | H6: spread | K6: 종목명 | L6: 만기일 | M6: 요일 | N6: 민평 | O6: 전일비 | P6: 이자 | Q6: 쿠폰 | R6: 상장액(백만) | S6: spread
A7: 3년 | B7: 국고19-3(01625-2206) | C7: 44722 | D7: 금 | E7: 1.216 | F7: -0.014 | G7: 7990000 | J7: 통 안 채 | K7: 통안01180-2108-02 | L7: 44410 | M7: 월 | N7: 1.247 | O7: -0.008 | P7: 이표 | Q7: 1.18 | R7: 5500000
B8: 국고18-9(02000-2112) | C8: 44540 | D8: 금 | E8: 1.247 | F8: -0.013 | G8: 9943000 | K8: 통안01585-2106-02 | L8: 44349 | M8: 수 | N8: 1.255 | O8: -0.005 | P8: 이표 | Q8: 1.585 | R8: 11700000
B9: 국고18-3(02250-2106) | C9: 44357 | D9: 목 | E9: 1.242 | F9: -0.013 | G9: 9469000 | H9: 3년 -2년 | K9: 통안01740-2104-02 | L9: 44288 | M9: 금 | N9: 1.26 | O9: 0 | P9: 이표 | Q9: 1.74 | R9: 13600000 | S9: 2년-1년
B10: 국고17-6(01750-2012) | C10: 44175 | D10: 목 | E10: 1.215 | F10: 0.006 | G10: 10595000 | H10: -0.031 | K10: 통안01810-2102-02 | L10: 44229 | M10: 화 | N10: 1.254 | O10: 0.006 | P10: 이표 | Q10: 1.81 | R10: 12950000 | S10: 0.022
B11: 국고17-2(01750-2006) | C11: 43992 | D11: 수 | E11: 1.166 | F11: 0.005 | G11: 7539000 | K11: 통안01930-2012-02 | L11: 44167 | M11: 수 | N11: 1.228 | O11: 0.005 | P11: 이표 | Q11: 1.93 | R11: 10900000
B12: 국고16-7(01250-1912) | C12: 43809 | D12: 화 | E12: 1.198 | F12: -0.002 | G12: 6599000 | K12: 통안02050-2010-02 | L12: 44109 | M12: 월 | N12: 1.226 | O12: 0.005 | P12: 이표 | Q12: 2.05 | R12: 11320000 | S12: 2년-1.5년
A13: 5년 | B13: 국고19-5(01375-2409) | C13: 45545 | D13: 화 | E13: 1.255 | F13: -0.02 | G13: 2634000 | K13: 통안02060-2008-02 | L13: 44045 | M13: 일 | N13: 1.225 | O13: 0.005 | P13: 이표 | Q13: 2.06 | R13: 10690000 | S13: -0.007
B14: 국고19-1(01875-2403) | C14: 45361 | D14: 일 | E14: 1.277 | F14: -0.02 | G14: 10675000 | H14: 5년-3년 | K14: 통안01480-2007-01 | L14: 44021 | M14: 목 | N14: 1.21 | O14: 0.003 | P14: 이표 | Q14: 1.48 | R14: 4550000
B15: 국고18-6(02250-2309) | C15: 45179 | D15: 일 | E15: 1.28 | F15: -0.018 | G15: 7342000 | H15: 0.061 | K15: 통안02140-2006-02 | L15: 43984 | M15: 화 | N15: 1.178 | O15: 0.005 | P15: 이표 | Q15: 2.14 | R15: 12020000
B16: 국고18-1(02375-2303) | C16: 44995 | D16: 금 | E16: 1.273 | F16: -0.017 | G16: 12566000 | K16: 통안01715-2005-01 | L16: 43960 | M16: 토 | N16: 1.197 | O16: 0.002 | P16: 이표 | Q16: 1.715 | R16: 5100000 | S16: 1.5년-1년
B17: 국고17-4(02000-2209) | C17: 44814 | D17: 토 | E17: 1.264 | F17: -0.011 | G17: 9626000 | H17: 5년-2년 | K17: 통안02120-2004-02 | L17: 43923 | M17: 목 | N17: 1.177 | O17: 0.001 | P17: 이표 | Q17: 2.12 | R17: 11590000 | S17: 0.029
B18: 국고16-10(01875-2203) | C18: 44630 | D18: 목 | E18: 1.25 | F18: -0.01 | G18: 13346000 | H18: 0.03 | K18: 통안01830-2003-01 | L18: 43899 | M18: 월 | N18: 1.205 | O18: 0 | P18: 이표 | Q18: 1.83 | R18: 5850000
B19: 국고16-4(01375-2109) | C19: 44449 | D19: 금 | E19: 1.244 | F19: -0.013 | G19: 9553000 | K19: 통안DC020-0303-1820 | L19: 43893 | M19: 화 | N19: 1.204 | O19: 0.001 | P19: 할인 | Q19: 1.193 | R19: 300000
B20: 국고15-9(02000-2103) | C20: 44265 | D20: 수 | E20: 1.218 | F20: 0.002 | G20: 12879000 | K20: 통안DC020-0218-1820 | L20: 43879 | M20: 화 | N20: 1.205 | O20: 0 | P20: 할인 | Q20: 1.183 | R20: 300000
B21: 국고15-4(02000-2009) | C21: 44084 | D21: 목 | E21: 1.195 | F21: 0.005 | G21: 12033000 | K21: 통안DC020-0204-1820 | L21: 43865 | M21: 화 | N21: 1.215 | O21: 0 | P21: 할인 | Q21: 1.291 | R21: 300000
B22: 국고15-1(02000-2003) | C22: 43900 | D22: 화 | E22: 1.168 | F22: 0 | G22: 7717000 | K22: 통안02160-2002-02 | L22: 43863 | M22: 일 | N22: 1.202 | O22: 0.001 | P22: 이표 | Q22: 2.16 | R22: 9460000
B23: 국고14-4(02750-1909) | C23: 43718 | D23: 화 | E23: 1.247 | F23: 0 | G23: 8734000 | K23: 통안DC020-0114-1820 | L23: 43844 | M23: 화 | N23: 1.223 | O23: 0 | P23: 할인 | Q23: 1.46 | R23: 300000
A24: 10년 | B24: 국고19-4(01875-2906) | C24: 47279 | D24: 일 | E24: 1.32 | F24: -0.025 | G24: 8343000 | K24: 통안01820-2001-01 | L24: 43839 | M24: 목 | N24: 1.23 | O24: 0 | P24: 이표 | Q24: 1.82 | R24: 5180000
B25: 국고18-10(02375-2812) | C25: 47097 | D25: 일 | E25: 1.325 | F25: -0.026 | G25: 11424000 | H25: 10년-5년 | K25: 통안DC019-1231-1820 | L25: 43830 | M25: 화 | N25: 1.24 | O25: 0 | P25: 할인 | Q25: 1.528 | R25: 300000
B26: 국고18-4(02625-2806) | C26: 46914 | D26: 토 | E26: 1.325 | F26: -0.026 | G26: 11437000 | H26: 0.043 | K26: 통안DC019-1217-1820 | L26: 43816 | M26: 화 | N26: 1.245 | O26: 0 | P26: 할인 | Q26: 1.528 | R26: 300000
B27: 국고17-7(02375-2712) | C27: 46731 | D27: 금 | E27: 1.322 | F27: -0.026 | G27: 11903000 | K27: 통안DC019-1203-1820 | L27: 43802 | M27: 화 | N27: 1.25 | O27: 0 | P27: 할인 | Q27: 1.607 | R27: 300000
B28: 국고17-3(02125-2706) | C28: 46548 | D28: 목 | E28: 1.317 | F28: -0.025 | G28: 12572000 | H28: 10년-3년 | K28: 통안DC019-1203-0910 | L28: 43802 | M28: 화 | N28: 1.266 | O28: 0 | P28: 할인 | Q28: 1.266 | R28: 800000
B29: 국고16-8(01500-2612) | C29: 46366 | D29: 목 | E29: 1.312 | F29: -0.024 | G29: 13063000 | H29: 0.104 | K29: 통안02060-1912-02 | L29: 43801 | M29: 월 | N29: 1.251 | O29: 0 | P29: 이표 | Q29: 2.06 | R29: 10330000
B30: 국고16-3(01875-2606) | C30: 46183 | D30: 수 | E30: 1.308 | F30: -0.023 | G30: 12212000 | K30: 통안DC019-1126-0910 | L30: 43795 | M30: 화 | N30: 1.278 | O30: 0 | P30: 할인 | Q30: 1.266 | R30: 800000
B31: 국고15-8(02250-2512) | C31: 46001 | D31: 수 | E31: 1.301 | F31: -0.022 | G31: 12790012 | H31: 10년-2년 | K31: 통안DC019-1119-1820 | L31: 43788 | M31: 화 | N31: 1.265 | O31: 0 | P31: 할인 | Q31: 1.637 | R31: 300000
B32: 국고15-2(02250-2506) | C32: 45818 | D32: 화 | E32: 1.295 | F32: -0.022 | G32: 15028000 | H32: 0.073 | K32: 통안DC019-1119-0910 | L32: 43788 | M32: 화 | N32: 1.265 | O32: 0 | P32: 할인 | Q32: 1.266 | R32: 900000
B33: 국고14-5(03000-2409) | C33: 45545 | D33: 화 | E33: 1.292 | F33: -0.02 | G33: 16366030 | K33: 통안DC019-1112-0910 | L33: 43781 | M33: 화 | N33: 1.268 | O33: 0 | P33: 할인 | Q33: 1.277 | R33: 900000
B34: 국고14-2(03500-2403) | C34: 45361 | D34: 일 | E34: 1.289 | F34: -0.02 | G34: 13194001 | K34: 통안01870-1911-01 | L34: 43778 | M34: 토 | N34: 1.268 | O34: 0 | P34: 이표 | Q34: 1.87 | R34: 3960000
B35: 국고13-6(03375-2309) | C35: 45179 | D35: 일 | E35: 1.281 | F35: -0.019 | G35: 12430026 | K35: 통안DC019-1105-1820 | L35: 43774 | M35: 화 | N35: 1.28 | O35: 0 | P35: 할인 | Q35: 1.716 | R35: 300000
B36: 국고13-2(03000-2303) | C36: 44995 | D36: 금 | E36: 1.276 | F36: -0.018 | G36: 12262020 | K36: 통안DC019-1105-0910 | L36: 43774 | M36: 화 | N36: 1.28 | O36: 0 | P36: 할인 | Q36: 1.336 | R36: 900000
B37: 국고12-3(03750-2206) | C37: 44722 | D37: 금 | E37: 1.257 | F37: -0.011 | G37: 15281500 | K37: 통안DC019-1029-0910 | L37: 43767 | M37: 화 | N37: 1.28 | O37: 0 | P37: 할인 | Q37: 1.415 | R37: 700000
B38: 국고11-3(04250-2106) | C38: 44357 | D38: 목 | E38: 1.222 | F38: -0.013 | G38: 17285959 | K38: 통안DC019-1022-0910 | L38: 43760 | M38: 화 | N38: 1.28 | O38: 0 | P38: 할인 | Q38: 1.485 | R38: 800000
B39: 국고10-3(05000-2006) | C39: 43992 | D39: 수 | E39: 1.11 | F39: 0.005 | G39: 11863000 | K39: 통안DC019-1015-1820 | L39: 43753 | M39: 화 | N39: 1.28 | O39: 0 | P39: 할인 | Q39: 1.764 | R39: 300000
B40: 물가18-5(01750-2806) | C40: 46914 | D40: 토 | E40: 0.63 | F40: -0.009 | G40: 1461000 | K40: 통안DC019-1015-0910 | L40: 43753 | M40: 화 | N40: 1.28 | O40: 0 | P40: 할인 | Q40: 1.515 | R40: 770000
B41: 물가16-5(01000-2606) | C41: 46183 | D41: 수 | E41: 0.405 | F41: -0.006 | G41: 2918020 | K41: 통안DC019-1008-0910 | L41: 43746 | M41: 화 | N41: 1.28 | O41: 0 | P41: 할인 | Q41: 1.534 | R41: 900000
B42: 물가15-5(01750-2506) | C42: 45818 | D42: 화 | E42: 0.27 | F42: -0.007 | G42: 683030 | K42: 통안01850-1910-02 | L42: 43740 | M42: 수 | N42: 1.28 | O42: 0 | P42: 이표 | Q42: 1.85 | R42: 8310000
...

Sheet 시평
A1: 그룹명 | B1: 3M | C1: 6M | D1: 9M | E1: 1Y | F1: 1Y6M | G1: 2Y | H1: 2Y6M | I1: 3Y | J1: 4Y | K1: 5Y | L1: 7Y | M1: 10Y | N1: 15Y | O1: 20Y | P1: 30Y | Q1: 50Y
A2: 국고채 | B2: 1.247 | C2: 1.203 | D2: 1.166 | E2: 1.158 | F2: 1.216 | G2: 1.243 | H2: 1.247 | I2: 1.216 | J2: 1.273 | K2: 1.277 | L2: 1.308 | M2: 1.32 | N2: 1.312 | O2: 1.307 | P2: 1.295 | Q2: 1.315
A3: 국민주택1종 | B3: 1.261 | C3: 1.239 | D3: 1.227 | E3: 1.252 | F3: 1.283 | G3: 1.296 | H3: 1.304 | I3: 1.307 | J3: 1.324 | K3: 1.345 | L3: - | M3: - | N3: - | O3: - | P3: - | Q3: -
A4: 국민주택2종 | B4: 1.004 | C4: 0.982 | D4: 0.971 | E4: 0.995 | F4: 1.026 | G4: 1.04 | H4: 1.051 | I4: 1.083 | J4: 1.115 | K4: 1.137 | L4: 1.237 | M4: 1.356 | N4: 1.445 | O4: 1.523 | P4: - | Q4: -
A5: 서울도시철도채 | B5: 1.299 | C5: 1.277 | D5: 1.266 | E5: 1.291 | F5: 1.322 | G5: 1.336 | H5: 1.344 | I5: 1.35 | J5: 1.371 | K5: 1.394 | L5: 1.413 | M5: - | N5: - | O5: - | P5: - | Q5: -
A6: 지역개발채 | B6: 1.299 | C6: 1.277 | D6: 1.266 | E6: 1.291 | F6: 1.322 | G6: 1.336 | H6: 1.344 | I6: 1.35 | J6: 1.371 | K6: 1.394 | L6: 1.413 | M6: 1.546 | N6: 1.69 | O6: 1.738 | P6: - | Q6: -
A7: MBS | B7: 1.371 | C7: 1.342 | D7: 1.335 | E7: 1.36 | F7: 1.394 | G7: 1.402 | H7: 1.385 | I7: 1.385 | J7: 1.397 | K7: 1.409 | L7: 1.405 | M7: 1.427 | N7: 1.415 | O7: 1.403 | P7: - | Q7: -
A8: 정부보증채 | B8: 1.331 | C8: 1.303 | D8: 1.296 | E8: 1.316 | F8: 1.353 | G8: 1.362 | H8: 1.347 | I8: 1.347 | J8: 1.364 | K8: 1.376 | L8: 1.373 | M8: 1.396 | N8: 1.383 | O8: 1.37 | P8: - | Q8: -
A9: 특수채AAA | B9: 1.368 | C9: 1.336 | D9: 1.329 | E9: 1.353 | F9: 1.388 | G9: 1.396 | H9: 1.379 | I9: 1.378 | J9: 1.393 | K9: 1.403 | L9: 1.402 | M9: 1.425 | N9: 1.41 | O9: 1.396 | P9: 1.372 | Q9: -
A10: 특수채AA+ | B10: 1.397 | C10: 1.378 | D10: 1.371 | E10: 1.401 | F10: 1.438 | G10: 1.446 | H10: 1.432 | I10: 1.433 | J10: 1.453 | K10: 1.495 | L10: 1.539 | M10: 1.619 | N10: 1.616 | O10: 1.61 | P10: - | Q10: -
A11: 특수채AA0 | B11: 1.456 | C11: 1.437 | D11: 1.433 | E11: 1.466 | F11: 1.51 | G11: 1.519 | H11: 1.507 | I11: 1.511 | J11: 1.54 | K11: 1.598 | L11: 1.646 | M11: 1.727 | N11: 1.764 | O11: 1.762 | P11: - | Q11: -
A12: 특수채AA- | B12: 1.541 | C12: 1.526 | D12: 1.527 | E12: 1.565 | F12: 1.607 | G12: 1.624 | H12: 1.619 | I12: 1.628 | J12: 1.654 | K12: 1.719 | L12: 1.761 | M12: 1.838 | N12: 1.883 | O12: 1.882 | P12: - | Q12: -
A13: 통안채 | B13: 1.278 | C13: 1.22 | D13: 1.198 | E13: 1.225 | F13: 1.254 | G13: 1.247 | H13: - | I13: - | J13: - | K13: - | L13: - | M13: - | N13: - | O13: - | P13: - | Q13: -
A14: 산금채 | B14: 1.417 | C14: 1.364 | D14: 1.336 | E14: 1.354 | F14: 1.38 | G14: 1.376 | H14: 1.368 | I14: 1.368 | J14: 1.386 | K14: 1.425 | L14: 1.431 | M14: 1.483 | N14: 1.49 | O14: 1.519 | P14: - | Q14: -
A15: 중금채 | B15: 1.417 | C15: 1.364 | D15: 1.336 | E15: 1.354 | F15: 1.38 | G15: 1.376 | H15: 1.373 | I15: 1.375 | J15: 1.403 | K15: 1.439 | L15: 1.457 | M15: 1.518 | N15: 1.526 | O15: 1.557 | P15: - | Q15: -
A16: 은행채AAA | B16: 1.436 | C16: 1.387 | D16: 1.364 | E16: 1.39 | F16: 1.42 | G16: 1.419 | H16: 1.413 | I16: 1.417 | J16: 1.433 | K16: 1.457 | L16: 1.496 | M16: 1.577 | N16: 1.586 | O16: 1.626 | P16: - | Q16: -
A17: 은행채AA+ | B17: 1.478 | C17: 1.434 | D17: 1.415 | E17: 1.449 | F17: 1.482 | G17: 1.49 | H17: 1.489 | I17: 1.493 | J17: 1.507 | K17: 1.522 | L17: 1.533 | M17: 1.624 | N17: 1.732 | O17: 1.819 | P17: - | Q17: -
A18: 은행채AA0 | B18: 1.628 | C18: 1.591 | D18: 1.575 | E18: 1.626 | F18: 1.671 | G18: 1.7 | H18: 1.729 | I18: 1.743 | J18: 1.762 | K18: 1.824 | L18: 1.859 | M18: 1.957 | N18: 2.074 | O18: 2.173 | P18: - | Q18: -
A19: 은행채AA- | B19: 1.791 | C19: 1.824 | D19: 1.827 | E19: 1.895 | F19: 1.931 | G19: 1.953 | H19: 1.967 | I19: 1.987 | J19: 2.006 | K19: 2.057 | L19: 2.105 | M19: 2.268 | N19: 2.31 | O19: 2.393 | P19: - | Q19: -
A20: 은행채A+ | B20: 1.879 | C20: 1.908 | D20: 1.911 | E20: 1.982 | F20: 2.035 | G20: 2.063 | H20: 2.081 | I20: 2.112 | J20: 2.137 | K20: 2.189 | L20: 2.258 | M20: 2.445 | N20: 2.52 | O20: 2.602 | P20: - | Q20: -
A21: 은행채A0 | B21: 1.969 | C21: 1.991 | D21: 1.989 | E21: 2.077 | F21: 2.137 | G21: 2.166 | H21: 2.183 | I21: 2.218 | J21: 2.244 | K21: 2.314 | L21: 2.385 | M21: 2.588 | N21: 2.655 | O21: 2.742 | P21: - | Q21: -
A22: 은행채A- | B22: 2.053 | C22: 2.086 | D22: 2.091 | E22: 2.158 | F22: 2.222 | G22: 2.254 | H22: 2.264 | I22: 2.299 | J22: 2.333 | K22: 2.398 | L22: 2.481 | M22: 2.695 | N22: 2.788 | O22: 2.893 | P22: - | Q22: -
A23: 비은행금융채AA+ | B23: 1.52 | C23: 1.512 | D23: 1.489 | E23: 1.507 | F23: 1.558 | G23: 1.564 | H23: 1.551 | I23: 1.551 | J23: 1.556 | K23: 1.601 | L23: 1.686 | M23: 1.992 | N23: 2.254 | O23: 2.336 | P23: - | Q23: -
A24: 비은행금융채AA0 | B24: 1.545 | C24: 1.529 | D24: 1.508 | E24: 1.521 | F24: 1.571 | G24: 1.576 | H24: 1.569 | I24: 1.575 | J24: 1.593 | K24: 1.747 | L24: 1.893 | M24: 2.229 | N24: 2.527 | O24: 2.612 | P24: - | Q24: -
A25: 비은행금융채AA- | B25: 1.579 | C25: 1.564 | D25: 1.542 | E25: 1.564 | F25: 1.634 | G25: 1.654 | H25: 1.648 | I25: 1.66 | J25: 1.699 | K25: 1.869 | L25: 2.065 | M25: 2.468 | N25: 2.755 | O25: 2.844 | P25: - | Q25: -
... A47: 보증사채A- | B47: 1.895 | C47: 1.924 | D47: 1.97 | E47: 2.024 | F47: 2.085 | G47: 2.167 | H47: 2.301 | I47: 2.493 | J47: 2.763 | K47: 3.143 | L47: 3.406 | M47: 3.987 | N47: 4.382 | O47: 4.599 | P47: - | Q47: -
A48: 특수은보회사채 | B48: 1.373 | C48: 1.391 | D48: 1.424 | E48: 1.475 | F48: 1.517 | G48: 1.521 | H48: 1.546 | I48: 1.548 | J48: 1.562 | K48: 1.578 | L48: 1.602 | M48: 1.645 | N48: - | O48: - | P48: - | Q48: -
A49: 시중은보회사채 | B49: 1.39 | C49: 1.395 | D49: 1.449 | E49: 1.507 | F49: 1.59 | G49: 1.676 | H49: 1.728 | I49: 1.752 | J49: 1.756 | K49: 1.772 | L49: 1.922 | M49: 2.152 | N49: - | O49: - | P49: - | Q49: -
A50: 지방은보회사채 | B50: 1.553 | C50: 1.568 | D50: 1.625 | E50: 1.695 | F50: 1.795 | G50: 1.808 | H50: 1.857 | I50: 1.889 | J50: 1.883 | K50: 1.93 | L50: 2.054 | M50: 2.589 | N50: - | O50: - | P50: - | Q50: -
A51: 기타보증회사채 | B51: 1.9 | C51: 2.183 | D51: 2.516 | E51: 2.772 | F51: 3.101 | G51: 3.547 | H51: 3.801 | I51: 4.136 | J51: 4.149 | K51: 4.267 | L51: 4.283 | M51: 4.443 | N51: - | O51: - | P51: - | Q51: -
A52: 무보증사채AAA | B52: 1.371 | C52: 1.389 | D52: 1.417 | E52: 1.462 | F52: 1.499 | G52: 1.507 | H52: 1.517 | I52: 1.522 | J52: 1.533 | K52: 1.538 | L52: 1.546 | M52: 1.592 | N52: 1.673 | O52: 1.765 | P52: - | Q52: -
A53: 무보증사채AA+ | B53: 1.4 | C53: 1.414 | D53: 1.442 | E53: 1.485 | F53: 1.521 | G53: 1.53 | H53: 1.543 | I53: 1.548 | J53: 1.56 | K53: 1.585 | L53: 1.675 | M53: 1.868 | N53: 2.063 | O53: 2.152 | P53: - | Q53: -
A54: 무보증사채AA0 | B54: 1.442 | C54: 1.455 | D54: 1.48 | E54: 1.521 | F54: 1.556 | G54: 1.567 | H54: 1.579 | I54: 1.584 | J54: 1.597 | K54: 1.646 | L54: 1.828 | M54: 2.253 | N54: 2.666 | O54: 2.768 | P54: - | Q54: -
A55: 무보증사채AA- | B55: 1.47 | C55: 1.484 | D55: 1.51 | E55: 1.552 | F55: 1.587 | G55: 1.595 | H55: 1.606 | I55: 1.611 | J55: 1.663 | K55: 1.751 | L55: 2.034 | M55: 2.605 | N55: 3.143 | O55: 3.313 | P55: - | Q55: -
A56: 무보증사채A+ | B56: 1.527 | C56: 1.543 | D56: 1.567 | E56: 1.605 | F56: 1.643 | G56: 1.654 | H56: 1.673 | I56: 1.784 | J56: 1.91 | K56: 2.147 | L56: 2.441 | M56: 3.01 | N56: 3.473 | O56: 3.663 | P56: - | Q56: -
A57: 무보증사채A0 | B57: 1.672 | C57: 1.695 | D57: 1.726 | E57: 1.767 | F57: 1.81 | G57: 1.828 | H57: 1.885 | I57: 2.052 | J57: 2.257 | K57: 2.559 | L57: 2.874 | M57: 3.464 | N57: 3.875 | O57: 4.104 | P57: - | Q57: -
A58: 무보증사채A- | B58: 1.896 | C58: 1.934 | D58: 1.973 | E58: 2.028 | F58: 2.087 | G58: 2.157 | H58: 2.283 | I58: 2.493 | J58: 2.756 | K58: 3.144 | L58: 3.409 | M58: 3.979 | N58: 4.385 | O58: 4.685 | P58: - | Q58: -
A59: 무보증사채BBB+ | B59: 2.538 | C59: 2.902 | D59: 3.263 | E59: 3.52 | F59: 3.932 | G59: 4.434 | H59: 4.772 | I59: 5.109 | J59: 5.163 | K59: 5.293 | L59: 5.379 | M59: 5.639 | N59: 6.058 | O59: 6.31 | P59: - | Q59: -
A60: 무보증사채BBB0 | B60: 2.918 | C60: 3.405 | D60: 3.844 | E60: 4.195 | F60: 4.742 | G60: 5.378 | H60: 5.805 | I60: 6.156 | J60: 6.205 | K60: 6.34 | L60: 6.43 | M60: 6.758 | N60: 7.17 | O60: 7.437 | P60: - | Q60: -
A61: 무보증사채BBB- | B61: 3.593 | C61: 4.202 | D61: 4.778 | E61: 5.183 | F61: 5.857 | G61: 6.537 | H61: 7.04 | I61: 7.525 | J61: 7.632 | K61: 7.761 | L61: 7.85 | M61: 8.184 | N61: 8.651 | O61: 8.899 | P61: - | Q61: -
...

Sheet 시가평가표
A1: 그룹명 | C1: 3M | D1: 6M | E1: 9M | F1: 1Y | G1: 1.5Y | H1: 2Y | I1: 2.5Y | J1: 3Y | K1: 4Y | L1: 5Y | M1: 7Y | N1: 10Y
A2: 국고채 | C2: =시평!B2 -> 1.247 | D2: =시평!C2 -> 1.203 | E2: =시평!D2 -> 1.166 | F2: =시평!E2 -> 1.158 | G2: =시평!F2 -> 1.216 | H2: =시평!G2 -> 1.243 | I2: =시평!H2 -> 1.247 | J2: =시평!I2 -> 1.216 | ... N2: =시평!M2 -> 1.32
A3: 국주 1종 | C3: =시평!B3 -> 1.261 | D3: =시평!C3 -> 1.239 | E3: =시평!D3 -> 1.227 | F3: =시평!E3 -> 1.252 | G3: =시평!F3 -> 1.283 | H3: =시평!G3 -> 1.296 | I3: =시평!H3 -> 1.304 | J3: =시평!I3 -> 1.307 | ... N3: =시평!M3 -> -
A4: MBS | C4: =시평!B7 -> 1.371 | D4: =시평!C7 -> 1.342 | E4: =시평!D7 -> 1.335 | F4: =시평!E7 -> 1.36 | G4: =시평!F7 -> 1.394 | H4: =시평!G7 -> 1.402 | I4: =시평!H7 -> 1.385 | J4: =시평!I7 -> 1.385 | ... N4: =시평!M7 -> 1.427
A5: 정부보증채 | C5: =시평!B8 -> 1.331 | D5: =시평!C8 -> 1.303 | E5: =시평!D8 -> 1.296 | F5: =시평!E8 -> 1.316 | G5: =시평!F8 -> 1.353 | H5: =시평!G8 -> 1.362 | I5: =시평!H8 -> 1.347 | J5: =시평!I8 -> 1.347 | ... N5: =시평!M8 -> 1.396
A6: 특수채 AAA | C6: =시평!B$9 -> 1.368 | D6: =시평!C$9 -> 1.336 | E6: =시평!D$9 -> 1.329 | F6: =시평!E$9 -> 1.353 | G6: =시평!F$9 -> 1.388 | H6: =시평!G$9 -> 1.396 | I6: =시평!H$9 -> 1.379 | J6: =시평!I$9 -> 1.378 | ... N6: =시평!M$9 -> 1.425
A7: 특수채 AA+ | C7: =시평!B$10 -> 1.397 | D7: =시평!C$10 -> 1.378 | E7: =시평!D$10 -> 1.371 | F7: =시평!E$10 -> 1.401 | G7: =시평!F$10 -> 1.438 | H7: =시평!G$10 -> 1.446 | I7: =시평!H$10 -> 1.432 | J7: =시평!I$10 -> 1.433 | ... N7: =시평!M$10 -> 1.619
A8: 산금채 | C8: =시평!B$14 -> 1.417 | D8: =시평!C$14 -> 1.364 | E8: =시평!D$14 -> 1.336 | F8: =시평!E$14 -> 1.354 | G8: =시평!F$14 -> 1.38 | H8: =시평!G$14 -> 1.376 | I8: =시평!H$14 -> 1.368 | J8: =시평!I$14 -> 1.368 | ... N8: =시평!M$14 -> 1.483
A9: 중금채 | C9: =시평!B$15 -> 1.417 | D9: =시평!C$15 -> 1.364 | E9: =시평!D$15 -> 1.336 | F9: =시평!E$15 -> 1.354 | G9: =시평!F$15 -> 1.38 | H9: =시평!G$15 -> 1.376 | I9: =시평!H$15 -> 1.373 | J9: =시평!I$15 -> 1.375 | ... N9: =시평!M$15 -> 1.518
A10: 은행채 AAA | C10: =시평!B$16 -> 1.436 | D10: =시평!C$16 -> 1.387 | E10: =시평!D$16 -> 1.364 | F10: =시평!E$16 -> 1.39 | G10: =시평!F$16 -> 1.42 | H10: =시평!G$16 -> 1.419 | I10: =시평!H$16 -> 1.413 | J10: =시평!I$16 -> 1.417 | ... N10: =시평!M$16 -> 1.577
A11: 은행채 AA+ | C11: =시평!B$17 -> 1.478 | D11: =시평!C$17 -> 1.434 | E11: =시평!D$17 -> 1.415 | F11: =시평!E$17 -> 1.449 | G11: =시평!F$17 -> 1.482 | H11: =시평!G$17 -> 1.49 | I11: =시평!H$17 -> 1.489 | J11: =시평!I$17 -> 1.493 | ... N11: =시평!M$17 -> 1.624
A12: 카드채 | B12: AA+ | C12: =시평!B32 -> 1.52 | D12: =시평!C32 -> 1.512 | E12: =시평!D32 -> 1.489 | F12: =시평!E32 -> 1.507 | G12: =시평!F32 -> 1.558 | H12: =시평!G32 -> 1.564 | I12: =시평!H32 -> 1.551 | J12: =시평!I32 -> 1.551 | ... N12: =시평!M32 -> 1.992
B13: AA0 | C13: =시평!B33 -> 1.545 | D13: =시평!C33 -> 1.529 | E13: =시평!D33 -> 1.508 | F13: =시평!E33 -> 1.521 | G13: =시평!F33 -> 1.571 | H13: =시평!G33 -> 1.576 | I13: =시평!H33 -> 1.569 | J13: =시평!I33 -> 1.575 | ... N13: =시평!M33 -> 2.229
B14: AA- | C14: =시평!B34 -> 1.579 | D14: =시평!C34 -> 1.564 | E14: =시평!D34 -> 1.542 | F14: =시평!E34 -> 1.564 | G14: =시평!F34 -> 1.634 | H14: =시평!G34 -> 1.654 | I14: =시평!H34 -> 1.648 | J14: =시평!I34 -> 1.66 | ... N14: =시평!M34 -> 2.468
B15: A+ | C15: =시평!B35 -> 1.643 | D15: =시평!C35 -> 1.637 | E15: =시평!D35 -> 1.62 | F15: =시평!E35 -> 1.661 | G15: =시평!F35 -> 1.715 | H15: =시평!G35 -> 1.769 | I15: =시평!H35 -> 1.799 | J15: =시평!I35 -> 1.923 | ... N15: =시평!M35 -> 2.933
A16: 무보증사채 | B16: AAA | C16: =시평!B52 -> 1.371 | D16: =시평!C52 -> 1.389 | E16: =시평!D52 -> 1.417 | F16: =시평!E52 -> 1.462 | G16: =시평!F52 -> 1.499 | H16: =시평!G52 -> 1.507 | I16: =시평!H52 -> 1.517 | J16: =시평!I52 -> 1.522 | ... N16: =시평!M52 -> 1.592
B17: AA+ | C17: =시평!B53 -> 1.4 | D17: =시평!C53 -> 1.414 | E17: =시평!D53 -> 1.442 | F17: =시평!E53 -> 1.485 | G17: =시평!F53 -> 1.521 | H17: =시평!G53 -> 1.53 | I17: =시평!H53 -> 1.543 | J17: =시평!I53 -> 1.548 | ... N17: =시평!M53 -> 1.868
B18: AA0 | C18: =시평!B54 -> 1.442 | D18: =시평!C54 -> 1.455 | E18: =시평!D54 -> 1.48 | F18: =시평!E54 -> 1.521 | G18: =시평!F54 -> 1.556 | H18: =시평!G54 -> 1.567 | I18: =시평!H54 -> 1.579 | J18: =시평!I54 -> 1.584 | ... N18: =시평!M54 -> 2.253
B19: AA- | C19: =시평!B55 -> 1.47 | D19: =시평!C55 -> 1.484 | E19: =시평!D55 -> 1.51 | F19: =시평!E55 -> 1.552 | G19: =시평!F55 -> 1.587 | H19: =시평!G55 -> 1.595 | I19: =시평!H55 -> 1.606 | J19: =시평!I55 -> 1.611 | ... N19: =시평!M55 -> 2.605
B20: A+ | C20: =시평!B56 -> 1.527 | D20: =시평!C56 -> 1.543 | E20: =시평!D56 -> 1.567 | F20: =시평!E56 -> 1.605 | G20: =시평!F56 -> 1.643 | H20: =시평!G56 -> 1.654 | I20: =시평!H56 -> 1.673 | J20: =시평!I56 -> 1.784 | ... N20: =시평!M56 -> 3.01
B21: A0 | C21: =시평!B57 -> 1.672 | D21: =시평!C57 -> 1.695 | E21: =시평!D57 -> 1.726 | F21: =시평!E57 -> 1.767 | G21: =시평!F57 -> 1.81 | H21: =시평!G57 -> 1.828 | I21: =시평!H57 -> 1.885 | J21: =시평!I57 -> 2.052 | ... N21: =시평!M57 -> 3.464
B22: A- | C22: =시평!B58 -> 1.896 | D22: =시평!C58 -> 1.934 | E22: =시평!D58 -> 1.973 | F22: =시평!E58 -> 2.028 | G22: =시평!F58 -> 2.087 | H22: =시평!G58 -> 2.157 | I22: =시평!H58 -> 2.283 | J22: =시평!I58 -> 2.493 | ... N22: =시평!M58 -> 3.979
A23: 그룹명 | C23: 1D | D23: 7D | E23: 10D | F23: 15D | G23: 1M | H23: 2M | I23: 3M | J23: 4M | K23: 6M | L23: 1Y | M23: 2Y
A24: CD | B24: AAA | C24: 1.47 | D24: 1.47 | E24: - | F24: 1.48 | G24: 1.48 | H24: 1.48 | I24: 1.49 | J24: 1.49 | K24: 1.49 | L24: 1.53 | M24: 1.53
Z68: =TODAY() -> 43712
