Workbook

Sheet 민평표
O3: Web : | P3: www.kidb.com
O4: Date: | P4: =TODAY() -> 43706
A5: 전일민평(국고/통안/예보/국주/지역채)
B6: 종목명 | C6: 만기일 | D6: 요일 | E6: 민평 | F6: 전일비 | G6: 상장액(백만) | H6: spread | K6: 종목명 | L6: 만기일 | M6: 요일 | N6: 민평 | O6: 전일비 | P6: 이자 | Q6: 쿠폰 | R6: 상장액(백만) | S6: spread
A7: 3년 | B7: 국고19-3(01625-2206) | C7: ='1'!D2 -> 44722 | D7: ='1'!E2 -> 금 | E7: ='1'!S2 -> 1.175 | F7: ='1'!S2-'1(t-1)'!S2 -> -0.002 | G7: ='1'!H2 -> 7990000 | J7: 통 안 채 | K7: ='1'!A63 -> 통안01180-2108-02 | L7: ='1'!D63 -> 44410 | M7: ='1'!E63 -> 월 | N7: ='1'!S63 -> 1.2 | O7: =N7-'1(t-1)'!S63 -> 0.013 | P7: =IF('1'!I63="이표고정","이표","할인") -> 이표 | Q7: ='1'!K63 -> 1.18 | R7: ='1'!H63 -> 5500000
B8: 국고18-9(02000-2112) | C8: ='1'!D3 -> 44540 | D8: ='1'!E3 -> 금 | E8: ='1'!S3 -> 1.201 | F8: ='1'!S3-'1(t-1)'!S3 -> -0.004 | G8: ='1'!H3 -> 9943000 | K8: ='1'!A64 -> 통안01585-2106-02 | L8: ='1'!D64 -> 44349 | M8: ='1'!E64 -> 수 | N8: ='1'!S64 -> 1.217 | O8: =N8-'1(t-1)'!S64 -> 0.009 | P8: =IF('1'!I64="이표고정","이표","할인") -> 이표 | Q8: ='1'!K64 -> 1.585 | R8: ='1'!H64 -> 11700000
B9: 국고18-3(02250-2106) | C9: ='1'!D4 -> 44357 | D9: ='1'!E4 -> 목 | E9: ='1'!S4 -> 1.2 | F9: ='1'!S4-'1(t-1)'!S4 -> -0.004 | G9: ='1'!H4 -> 9469000 | H9: 3년 -2년 | K9: ='1'!A65 -> 통안01740-2104-02 | L9: ='1'!D65 -> 44288 | M9: ='1'!E65 -> 금 | N9: ='1'!S65 -> 1.216 | O9: =N9-'1(t-1)'!S65 -> 0.006 | P9: =IF('1'!I65="이표고정","이표","할인") -> 이표 | Q9: ='1'!K65 -> 1.74 | R9: ='1'!H65 -> 13600000 | S9: 2년-1년
B10: 국고17-6(01750-2012) | C10: ='1'!D5 -> 44175 | D10: ='1'!E5 -> 목 | E10: ='1'!S5 -> 1.156 | F10: ='1'!S5-'1(t-1)'!S5 -> 0.005 | G10: ='1'!H5 -> 10595000 | H10: =E7-N7 -> -0.025 | K10: ='1'!A66 -> 통안01810-2102-02 | L10: ='1'!D66 -> 44229 | M10: ='1'!E66 -> 화 | N10: ='1'!S66 -> 1.19 | O10: =N10-'1(t-1)'!S66 -> 0.005 | P10: =IF('1'!I66="이표고정","이표","할인") -> 이표 | Q10: ='1'!K66 -> 1.81 | R10: ='1'!H66 -> 12950000 | S10: =N7-N13 -> 0.031
B11: 국고17-2(01750-2006) | C11: ='1'!D6 -> 43992 | D11: ='1'!E6 -> 수 | E11: ='1'!S6 -> 1.135 | F11: ='1'!S6-'1(t-1)'!S6 -> 0.01 | G11: ='1'!H6 -> 7539000 | K11: ='1'!A67 -> 통안01930-2012-02 | L11: ='1'!D67 -> 44167 | M11: ='1'!E67 -> 수 | N11: ='1'!S67 -> 1.176 | O11: =N11-'1(t-1)'!S67 -> 0.004 | P11: =IF('1'!I67="이표고정","이표","할인") -> 이표 | Q11: ='1'!K67 -> 1.93 | R11: ='1'!H67 -> 10900000
B12: 국고16-7(01250-1912) | C12: ='1'!D7 -> 43809 | D12: ='1'!E7 -> 화 | E12: ='1'!S7 -> 1.198 | F12: ='1'!S7-'1(t-1)'!S7 -> -0.008 | G12: ='1'!H7 -> 6599000 | K12: ='1'!A68 -> 통안02050-2010-02 | L12: ='1'!D68 -> 44109 | M12: ='1'!E68 -> 월 | N12: ='1'!S68 -> 1.17 | O12: =N12-'1(t-1)'!S68 -> 0.01 | P12: =IF('1'!I68="이표고정","이표","할인") -> 이표 | Q12: ='1'!K68 -> 2.05 | R12: ='1'!H68 -> 11320000 | S12: 2년-1.5년
A13: 5년 | B13: 국고19-5(01375-2409) | C13: ='1'!D9 -> 45545 | D13: ='1'!E9 -> 화 | E13: ='1'!S9 -> 1.191 | F13: ='1'!S9-'1(t-1)'!S9 -> 0 | G13: ='1'!H9 -> 1234000 | K13: ='1'!A69 -> 통안02060-2008-02 | L13: ='1'!D69 -> 44045 | M13: ='1'!E69 -> 일 | N13: ='1'!S69 -> 1.169 | O13: =N13-'1(t-1)'!S69 -> 0.004 | P13: =IF('1'!I69="이표고정","이표","할인") -> 이표 | Q13: ='1'!K69 -> 2.06 | R13: ='1'!H69 -> 10690000 | S13: =N7-N10 -> 0.01
B14: 국고19-1(01875-2403) | C14: ='1'!D10 -> 45361 | D14: ='1'!E10 -> 일 | E14: ='1'!S10 -> 1.21 | F14: ='1'!S10-'1(t-1)'!S10 -> 0 | G14: ='1'!H10 -> 10675000 | H14: 5년-3년 | K14: ='1'!A70 -> 통안01480-2007-01 | L14: ='1'!D70 -> 44021 | M14: ='1'!E70 -> 목 | N14: ='1'!S70 -> 1.164 | O14: =N14-'1(t-1)'!S70 -> 0.008 | P14: =IF('1'!I70="이표고정","이표","할인") -> 이표 | Q14: ='1'!K70 -> 1.48 | R14: ='1'!H70 -> 4550000
B15: 국고18-6(02250-2309) | C15: ='1'!D11 -> 45179 | D15: ='1'!E11 -> 일 | E15: ='1'!S11 -> 1.215 | F15: ='1'!S11-'1(t-1)'!S11 -> -0.002 | G15: ='1'!H11 -> 7342000 | H15: =E14-E7 -> 0.035 | K15: ='1'!A71 -> 통안02140-2006-02 | L15: ='1'!D71 -> 43984 | M15: ='1'!E71 -> 화 | N15: ='1'!S71 -> 1.146 | O15: =N15-'1(t-1)'!S71 -> 0.003 | P15: =IF('1'!I71="이표고정","이표","할인") -> 이표 | Q15: ='1'!K71 -> 2.14 | R15: ='1'!H71 -> 12020000
B16: 국고18-1(02375-2303) | C16: ='1'!D12 -> 44995 | D16: ='1'!E12 -> 금 | E16: ='1'!S12 -> 1.213 | F16: ='1'!S12-'1(t-1)'!S12 -> -0.003 | G16: ='1'!H12 -> 12566000 | K16: ='1'!A72 -> 통안01715-2005-01 | L16: ='1'!D72 -> 43960 | M16: ='1'!E72 -> 토 | N16: ='1'!S72 -> 1.171 | O16: =N16-'1(t-1)'!S72 -> 0.002 | P16: =IF('1'!I72="이표고정","이표","할인") -> 이표 | Q16: ='1'!K72 -> 1.715 | R16: ='1'!H72 -> 5100000 | S16: 1.5년-1년
B17: 국고17-4(02000-2209) | C17: ='1'!D13 -> 44814 | D17: ='1'!E13 -> 토 | E17: ='1'!S13 -> 1.21 | F17: ='1'!S13-'1(t-1)'!S13 -> -0.004 | G17: ='1'!H13 -> 9626000 | H17: 5년-2년 | K17: ='1'!A73 -> 통안02120-2004-02 | L17: ='1'!D73 -> 43923 | M17: ='1'!E73 -> 목 | N17: ='1'!S73 -> 1.166 | O17: =N17-'1(t-1)'!S73 -> 0.002 | P17: =IF('1'!I73="이표고정","이표","할인") -> 이표 | Q17: ='1'!K73 -> 2.12 | R17: ='1'!H73 -> 11590000 | S17: =N10-N13 -> 0.021
B18: 국고16-10(01875-2203) | C18: ='1'!D14 -> 44630 | D18: ='1'!E14 -> 목 | E18: ='1'!S14 -> 1.205 | F18: ='1'!S14-'1(t-1)'!S14 -> -0.005 | G18: ='1'!H14 -> 13346000 | H18: =E14-N7 -> 0.01 | K18: ='1'!A74 -> 통안01830-2003-01 | L18: ='1'!D74 -> 43899 | M18: ='1'!E74 -> 월 | N18: ='1'!S74 -> 1.189 | O18: =N18-'1(t-1)'!S74 -> 0.002 | P18: =IF('1'!I74="이표고정","이표","할인") -> 이표 | Q18: ='1'!K74 -> 1.83 | R18: ='1'!H74 -> 5850000
B19: 국고16-4(01375-2109) | C19: ='1'!D15 -> 44449 | D19: ='1'!E15 -> 금 | E19: ='1'!S15 -> 1.201 | F19: ='1'!S15-'1(t-1)'!S15 -> -0.004 | G19: ='1'!H15 -> 9553000 | K19: ='1'!A75 -> 통안DC020-0218-1820 | L19: ='1'!D75 -> 43879 | M19: ='1'!E75 -> 화 | N19: ='1'!S75 -> 1.191 | O19: =N19-'1(t-1)'!S75 -> 0.003 | P19: =IF('1'!I75="이표고정","이표","할인") -> 할인 | Q19: ='1'!K75 -> 1.183 | R19: ='1'!H75 -> 300000
B20: 국고15-9(02000-2103) | C20: ='1'!D16 -> 44265 | D20: ='1'!E16 -> 수 | E20: ='1'!S16 -> 1.16 | F20: ='1'!S16-'1(t-1)'!S16 -> 0.001 | G20: ='1'!H16 -> 12879000 | K20: ='1'!A76 -> 통안DC020-0204-1820 | L20: ='1'!D76 -> 43865 | M20: ='1'!E76 -> 화 | N20: ='1'!S76 -> 1.208 | O20: =N20-'1(t-1)'!S76 -> 0 | P20: =IF('1'!I76="이표고정","이표","할인") -> 할인 | Q20: ='1'!K76 -> 1.291 | R20: ='1'!H76 -> 300000
B21: 국고15-4(02000-2009) | C21: ='1'!D17 -> 44084 | D21: ='1'!E17 -> 목 | E21: ='1'!S17 -> 1.155 | F21: ='1'!S17-'1(t-1)'!S17 -> 0.006 | G21: ='1'!H17 -> 12033000 | K21: ='1'!A77 -> 통안02160-2002-02 | L21: ='1'!D77 -> 43863 | M21: ='1'!E77 -> 일 | N21: ='1'!S77 -> 1.193 | O21: =N21-'1(t-1)'!S77 -> 0.003 | P21: =IF('1'!I77="이표고정","이표","할인") -> 이표 | Q21: ='1'!K77 -> 2.16 | R21: ='1'!H77 -> 9460000
B22: 국고15-1(02000-2003) | C22: ='1'!D18 -> 43900 | D22: ='1'!E18 -> 화 | E22: ='1'!S18 -> 1.158 | F22: ='1'!S18-'1(t-1)'!S18 -> 0 | G22: ='1'!H18 -> 7717000 | K22: ='1'!A78 -> 통안DC020-0114-1820 | L22: ='1'!D78 -> 43844 | M22: ='1'!E78 -> 화 | N22: ='1'!S78 -> 1.216 | O22: =N22-'1(t-1)'!S78 -> 0.001 | P22: =IF('1'!I78="이표고정","이표","할인") -> 할인 | Q22: ='1'!K78 -> 1.46 | R22: ='1'!H78 -> 300000
B23: 국고14-4(02750-1909) | C23: ='1'!D19 -> 43718 | D23: ='1'!E19 -> 화 | E23: ='1'!S19 -> 1.245 | F23: ='1'!S19-'1(t-1)'!S19 -> -0.004 | G23: ='1'!H19 -> 8734000 | K23: ='1'!A79 -> 통안01820-2001-01 | L23: ='1'!D79 -> 43839 | M23: ='1'!E79 -> 목 | N23: ='1'!S79 -> 1.223 | O23: =N23-'1(t-1)'!S79 -> 0.002 | P23: =IF('1'!I79="이표고정","이표","할인") -> 이표 | Q23: ='1'!K79 -> 1.82 | R23: ='1'!H79 -> 5180000
A24: 10년 | B24: 국고19-4(01875-2906) | C24: ='1'!D21 -> 47279 | D24: ='1'!E21 -> 일 | E24: ='1'!S21 -> 1.241 | F24: ='1'!S21-'1(t-1)'!S21 -> -0.009 | G24: ='1'!H21 -> 8343000 | K24: ='1'!A80 -> 통안DC019-1231-1820 | L24: ='1'!D80 -> 43830 | M24: ='1'!E80 -> 화 | N24: ='1'!S80 -> 1.231 | O24: =N24-'1(t-1)'!S80 -> 0.001 | P24: =IF('1'!I80="이표고정","이표","할인") -> 할인 | Q24: ='1'!K80 -> 1.528 | R24: ='1'!H80 -> 300000
B25: 국고18-10(02375-2812) | C25: ='1'!D22 -> 47097 | D25: ='1'!E22 -> 일 | E25: ='1'!S22 -> 1.25 | F25: ='1'!S22-'1(t-1)'!S22 -> -0.01 | G25: ='1'!H22 -> 11424000 | H25: 10년-5년 | K25: ='1'!A81 -> 통안DC019-1217-1820 | L25: ='1'!D81 -> 43816 | M25: ='1'!E81 -> 화 | N25: ='1'!S81 -> 1.236 | O25: =N25-'1(t-1)'!S81 -> 0.002 | P25: =IF('1'!I81="이표고정","이표","할인") -> 할인 | Q25: ='1'!K81 -> 1.528 | R25: ='1'!H81 -> 300000
B26: 국고18-4(02625-2806) | C26: ='1'!D23 -> 46914 | D26: ='1'!E23 -> 토 | E26: ='1'!S23 -> 1.25 | F26: ='1'!S23-'1(t-1)'!S23 -> -0.01 | G26: ='1'!H23 -> 11437000 | H26: =E24-E14 -> 0.031 | K26: ='1'!A82 -> 통안DC019-1203-1820 | L26: ='1'!D82 -> 43802 | M26: ='1'!E82 -> 화 | N26: ='1'!S82 -> 1.24 | O26: =N26-'1(t-1)'!S82 -> 0.001 | P26: =IF('1'!I82="이표고정","이표","할인") -> 할인 | Q26: ='1'!K82 -> 1.607 | R26: ='1'!H82 -> 300000
B27: 국고17-7(02375-2712) | C27: ='1'!D24 -> 46731 | D27: ='1'!E24 -> 금 | E27: ='1'!S24 -> 1.246 | F27: ='1'!S24-'1(t-1)'!S24 -> -0.01 | G27: ='1'!H24 -> 11903000 | K27: ='1'!A83 -> 통안02060-1912-02 | L27: ='1'!D83 -> 43801 | M27: ='1'!E83 -> 월 | N27: ='1'!S83 -> 1.242 | O27: =N27-'1(t-1)'!S83 -> 0.002 | P27: =IF('1'!I83="이표고정","이표","할인") -> 이표 | Q27: ='1'!K83 -> 2.06 | R27: ='1'!H83 -> 10330000
B28: 국고17-3(02125-2706) | C28: ='1'!D25 -> 46548 | D28: ='1'!E25 -> 목 | E28: ='1'!S25 -> 1.241 | F28: ='1'!S25-'1(t-1)'!S25 -> -0.008 | G28: ='1'!H25 -> 12572000 | H28: 10년-3년 | K28: ='1'!A84 -> 통안DC019-1126-0910 | L28: ='1'!D84 -> 43795 | M28: ='1'!E84 -> 화 | N28: ='1'!S84 -> 1.272 | O28: =N28-'1(t-1)'!S84 -> 0 | P28: =IF('1'!I84="이표고정","이표","할인") -> 할인 | Q28: ='1'!K84 -> 1.266 | R28: ='1'!H84 -> 800000
B29: 국고16-8(01500-2612) | C29: ='1'!D26 -> 46366 | D29: ='1'!E26 -> 목 | E29: ='1'!S26 -> 1.237 | F29: ='1'!S26-'1(t-1)'!S26 -> -0.007 | G29: ='1'!H26 -> 13063000 | H29: =E24-E7 -> 0.066 | K29: ='1'!A85 -> 통안DC019-1119-1820 | L29: ='1'!D85 -> 43788 | M29: ='1'!E85 -> 화 | N29: ='1'!S85 -> 1.258 | O29: =N29-'1(t-1)'!S85 -> 0.003 | P29: =IF('1'!I85="이표고정","이표","할인") -> 할인 | Q29: ='1'!K85 -> 1.637 | R29: ='1'!H85 -> 300000
B30: 국고16-3(01875-2606) | C30: ='1'!D27 -> 46183 | D30: ='1'!E27 -> 수 | E30: ='1'!S27 -> 1.235 | F30: ='1'!S27-'1(t-1)'!S27 -> -0.008 | G30: ='1'!H27 -> 12212000 | K30: ='1'!A86 -> 통안DC019-1119-0910 | L30: ='1'!D86 -> 43788 | M30: ='1'!E86 -> 화 | N30: ='1'!S86 -> 1.258 | O30: =N30-'1(t-1)'!S86 -> 0.002 | P30: =IF('1'!I86="이표고정","이표","할인") -> 할인 | Q30: ='1'!K86 -> 1.266 | R30: ='1'!H86 -> 900000
B31: 국고15-8(02250-2512) | C31: ='1'!D28 -> 46001 | D31: ='1'!E28 -> 수 | E31: ='1'!S28 -> 1.229 | F31: ='1'!S28-'1(t-1)'!S28 -> -0.006 | G31: ='1'!H28 -> 12790012 | H31: 10년-2년 | K31: ='1'!A87 -> 통안DC019-1112-0910 | L31: ='1'!D87 -> 43781 | M31: ='1'!E87 -> 화 | N31: ='1'!S87 -> 1.263 | O31: =N31-'1(t-1)'!S87 -> 0.002 | P31: =IF('1'!I87="이표고정","이표","할인") -> 할인 | Q31: ='1'!K87 -> 1.277 | R31: ='1'!H87 -> 900000
B32: 국고15-2(02250-2506) | C32: ='1'!D29 -> 45818 | D32: ='1'!E29 -> 화 | E32: ='1'!S29 -> 1.224 | F32: ='1'!S29-'1(t-1)'!S29 -> -0.006 | G32: ='1'!H29 -> 15028000 | H32: =E24-N7 -> 0.041 | K32: ='1'!A88 -> 통안01870-1911-01 | L32: ='1'!D88 -> 43778 | M32: ='1'!E88 -> 토 | N32: ='1'!S88 -> 1.263 | O32: =N32-'1(t-1)'!S88 -> 0 | P32: =IF('1'!I88="이표고정","이표","할인") -> 이표 | Q32: ='1'!K88 -> 1.87 | R32: ='1'!H88 -> 3960000
B33: 국고14-5(03000-2409) | C33: ='1'!D30 -> 45545 | D33: ='1'!E30 -> 화 | E33: ='1'!S30 -> 1.222 | F33: ='1'!S30-'1(t-1)'!S30 -> -0.003 | G33: ='1'!H30 -> 16366030 | K33: ='1'!A89 -> 통안DC019-1105-1820 | L33: ='1'!D89 -> 43774 | M33: ='1'!E89 -> 화 | N33: ='1'!S89 -> 1.275 | O33: =N33-'1(t-1)'!S89 -> 0 | P33: =IF('1'!I89="이표고정","이표","할인") -> 할인 | Q33: ='1'!K89 -> 1.716 | R33: ='1'!H89 -> 300000
B34: 국고14-2(03500-2403) | C34: ='1'!D31 -> 45361 | D34: ='1'!E31 -> 일 | E34: ='1'!S31 -> 1.222 | F34: ='1'!S31-'1(t-1)'!S31 -> -0.003 | G34: ='1'!H31 -> 13194001 | K34: ='1'!A90 -> 통안DC019-1105-0910 | L34: ='1'!D90 -> 43774 | M34: ='1'!E90 -> 화 | N34: ='1'!S90 -> 1.275 | O34: =N34-'1(t-1)'!S90 -> 0 | P34: =IF('1'!I90="이표고정","이표","할인") -> 할인 | Q34: ='1'!K90 -> 1.336 | R34: ='1'!H90 -> 900000
B35: 국고13-6(03375-2309) | C35: ='1'!D32 -> 45179 | D35: ='1'!E32 -> 일 | E35: ='1'!S32 -> 1.215 | F35: ='1'!S32-'1(t-1)'!S32 -> -0.003 | G35: ='1'!H32 -> 12430026 | K35: ='1'!A91 -> 통안DC019-1029-0910 | L35: ='1'!D91 -> 43767 | M35: ='1'!E91 -> 화 | N35: ='1'!S91 -> 1.275 | O35: =N35-'1(t-1)'!S91 -> 0 | P35: =IF('1'!I91="이표고정","이표","할인") -> 할인 | Q35: ='1'!K91 -> 1.415 | R35: ='1'!H91 -> 700000
B36: 국고13-2(03000-2303) | C36: ='1'!D33 -> 44995 | D36: ='1'!E33 -> 금 | E36: ='1'!S33 -> 1.215 | F36: ='1'!S33-'1(t-1)'!S33 -> -0.003 | G36: ='1'!H33 -> 12262020 | K36: ='1'!A92 -> 통안DC019-1022-0910 | L36: ='1'!D92 -> 43760 | M36: ='1'!E92 -> 화 | N36: ='1'!S92 -> 1.275 | O36: =N36-'1(t-1)'!S92 -> 0 | P36: =IF('1'!I92="이표고정","이표","할인") -> 할인 | Q36: ='1'!K92 -> 1.485 | R36: ='1'!H92 -> 800000
B37: 국고12-3(03750-2206) | C37: ='1'!D34 -> 44722 | D37: ='1'!E34 -> 금 | E37: ='1'!S34 -> 1.206 | F37: ='1'!S34-'1(t-1)'!S34 -> -0.004 | G37: ='1'!H34 -> 15281500 | K37: ='1'!A93 -> 통안DC019-1015-1820 | L37: ='1'!D93 -> 43753 | M37: ='1'!E93 -> 화 | N37: ='1'!S93 -> 1.275 | O37: =N37-'1(t-1)'!S93 -> 0 | P37: =IF('1'!I93="이표고정","이표","할인") -> 할인 | Q37: ='1'!K93 -> 1.764 | R37: ='1'!H93 -> 300000
B38: 국고11-3(04250-2106) | C38: ='1'!D35 -> 44357 | D38: ='1'!E35 -> 목 | E38: ='1'!S35 -> 1.179 | F38: ='1'!S35-'1(t-1)'!S35 -> -0.003 | G38: ='1'!H35 -> 17285959 | K38: ='1'!A94 -> 통안DC019-1015-0910 | L38: ='1'!D94 -> 43753 | M38: ='1'!E94 -> 화 | N38: ='1'!S94 -> 1.275 | O38: =N38-'1(t-1)'!S94 -> 0 | P38: =IF('1'!I94="이표고정","이표","할인") -> 할인 | Q38: ='1'!K94 -> 1.515 | R38: ='1'!H94 -> 770000
B39: 국고10-3(05000-2006) | C39: ='1'!D36 -> 43992 | D39: ='1'!E36 -> 수 | E39: ='1'!S36 -> 1.078 | F39: ='1'!S36-'1(t-1)'!S36 -> 0.001 | G39: ='1'!H36 -> 11863000 | K39: ='1'!A95 -> 통안DC019-1008-0910 | L39: ='1'!D95 -> 43746 | M39: ='1'!E95 -> 화 | N39: ='1'!S95 -> 1.275 | O39: =N39-'1(t-1)'!S95 -> 0 | P39: =IF('1'!I95="이표고정","이표","할인") -> 할인 | Q39: ='1'!K95 -> 1.534 | R39: ='1'!H95 -> 900000
B40: 물가18-5(01750-2806) | C40: ='1'!D37 -> 46914 | D40: ='1'!E37 -> 토 | E40: ='1'!S37 -> 0.63 | F40: ='1'!S37-'1(t-1)'!S37 -> -0.015 | G40: ='1'!H37 -> 1461000 | K40: ='1'!A96 -> 통안01850-1910-02 | L40: ='1'!D96 -> 43740 | M40: ='1'!E96 -> 수 | N40: ='1'!S96 -> 1.275 | O40: =N40-'1(t-1)'!S96 -> 0 | P40: =IF('1'!I96="이표고정","이표","할인") -> 이표 | Q40: ='1'!K96 -> 1.85 | R40: ='1'!H96 -> 8310000
B41: 물가16-5(01000-2606) | C41: ='1'!D38 -> 46183 | D41: ='1'!E38 -> 수 | E41: ='1'!S38 -> 0.407 | F41: ='1'!S38-'1(t-1)'!S38 -> -0.012 | G41: ='1'!H38 -> 2918020 | K41: ='1'!A97 -> 통안DC019-1001-1820 | L41: ='1'!D97 -> 43739 | M41: ='1'!E97 -> 화 | N41: ='1'!S97 -> 1.275 | O41: =N41-'1(t-1)'!S97 -> 0 | P41: =IF('1'!I97="이표고정","이표","할인") -> 할인 | Q41: ='1'!K97 -> 1.784 | R41: ='1'!H97 -> 310000
B42: 물가15-5(01750-2506) | C42: ='1'!D39 -> 45818 | D42: ='1'!E39 -> 화 | E42: ='1'!S39 -> 0.273 | F42: ='1'!S39-'1(t-1)'!S39 -> -0.012 | G42: ='1'!H39 -> 683030 | K42: ='1'!A98 -> 통안DC019-1001-0910 | L42: ='1'!D98 -> 43739 | M42: ='1'!E98 -> 화 | N42: ='1'!S98 -> 1.275 | O42: =N42-'1(t-1)'!S98 -> 0 | P42: =IF('1'!I98="이표고정","이표","할인") -> 할인 | Q42: ='1'!K98 -> 1.574 | R42: ='1'!H98 -> 900000
...

Sheet 1
A1: 종목명 | B1: 발행일 | C1: 일 | D1: 만기일 | E1: 일 | F1: 잔존일 | G1: 발행액(백만) | H1: 상장잔액(백만) | I1: 이자유형 | J1: 주기 | K1: 표면금리 | L1: 주식옵션 | M1: 중도상환 | N1: ABS | O1: 보증유형 | P1: 상장여부 | Q1: 공사모 | R1: 순위 | S1: 민평3사 | T1: 시가 | U1: C.가격 | V1: 신용그룹 | W1: 신용그룹코드 | X1: PPC100 | Y1: 듀레이션 | Z1: 표준코드
A2: 국고01625-2206(19-3) | B2: 43626 | C2: 월 | D2: 44722 | E2: 금 | F2: 0002-09-12 | G2: 7990000 | H2: 7990000 | I2: 이표고정 | J2: 6 | K2: 1.625 | L2: - | M2: - | N2: X | O2: 무보증 | P2: 상장 | Q2: 공모직접 | R2: 선 | S2: 1.175 | T2: 10158.2 | U2: 10122.69 | V2: 국고채 | W2: 1010000 | X2: 2.7074 | Y2: 2.7215 | Z2: KR103501G968*058
A3: 국고02000-2112(18-9) | B3: 43444 | C3: 월 | D3: 44540 | E3: 금 | F3: 0002-03-11 | G3: 9943000 | H3: 9943000 | I3: 이표고정 | J3: 6 | K3: 2 | L3: - | M3: - | N3: X | O3: 무보증 | P3: 상장 | Q3: 공모직접 | R3: 선 | S3: 1.201 | T3: 10222.8 | U3: 10178.94 | V3: 국고채 | W3: 1010000 | X3: 2.2206 | Y3: 2.2337 | Z3: KR103501G8C1*058
A4: 국고02250-2106(18-3) | B4: 43261 | C4: 일 | D4: 44357 | E4: 목 | F4: 0001-09-12 | G4: 9469000 | H4: 9469000 | I4: 이표고정 | J4: 6 | K4: 2.25 | L4: - | M4: - | N4: X | O4: 무보증 | P4: 상장 | Q4: 공모직접 | R4: 선 | S4: 1.2 | T4: 10233.56 | U4: 10184.38 | V4: 국고채 | W4: 1010000 | X4: 1.7391 | Y4: 1.7481 | Z4: KR103501G869*058
A5: 국고01750-2012(17-6) | B5: 43079 | C5: 일 | D5: 44175 | E5: 목 | F5: 0001-03-11 | G5: 10705000 | H5: 10595000 | I5: 이표고정 | J5: 6 | K5: 1.75 | L5: - | M5: - | N5: X | O5: 무보증 | P5: 상장 | Q5: 공모직접 | R5: 선 | S5: 1.156 | T5: 10113.39 | U5: 10075.36 | V5: 국고채 | W5: 1010000 | X5: 1.262 | Y5: 1.2692 | Z5: KR103501G7C3*058
A6: 국고01750-2006(17-2) | B6: 42896 | C6: 토 | D6: 43992 | E6: 수 | F6: 0000-09-12 | G6: 9423000 | H6: 7539000 | I6: 이표고정 | J6: 6 | K6: 1.75 | L6: - | M6: - | N6: X | O6: 무보증 | P6: 상장 | Q6: 공모직접 | R6: 선 | S6: 1.135 | T6: 10085.86 | U6: 10048.39 | V6: 국고채 | W6: 1010000 | X6: 0.7734 | Y6: 0.777 | Z6: KR103501G760*058
A7: 국고01250-1912(16-7) | B7: 42714 | C7: 토 | D7: 43809 | E7: 화 | F7: 0000-03-11 | G7: 11710000 | H7: 6599000 | I7: 이표고정 | J7: 6 | K7: 1.25 | L7: - | M7: - | N7: X | O7: 무보증 | P7: 상장 | Q7: 공모직접 | R7: 선 | S7: 1.198 | T7: 10028.67 | U7: 10001.45 | V7: 국고채 | W7: 1010000 | X7: 0.2804 | Y7: 0.2814 | Z7: KR103501G6C5*058
A8: - | B8: - | D8: - | F8: - | G8: - | H8: - | I8: - | J8: - | K8: 1.5 | L8: - | M8: - | N8: X | O8: - | P8: 비상장 | Q8: - | R8: - | S8: - | T8: - | V8: - | W8: - | X8: - | Y8: - | Z8: -
A9: 국고01375-2409(19-5) | B9: 43718 | C9: 화 | D9: 45545 | E9: 화 | F9: 0005-00-12 | G9: 1234000 | H9: 1234000 | I9: 이표고정 | J9: 6 | K9: 1.375 | L9: - | M9: - | N9: X | O9: 무보증 | P9: 상장 | Q9: 공모직접 | R9: 선 | S9: 1.191 | T9: 10084.97 | U9: 10084.65 | V9: 국고채 | W9: 1010000 | X9: 4.8564 | Y9: 4.8827 | Z9: KR103501G992*058
A10: 국고01875-2403(19-1) | B10: 43534 | C10: 일 | D10: 45361 | E10: 일 | F10: 0004-06-10 | G10: 10675000 | H10: 10675000 | I10: 이표고정 | J10: 6 | K10: 1.875 | L10: - | M10: - | N10: X | O10: 무보증 | P10: 상장 | Q10: 공모직접 | R10: 선 | S10: 1.21 | T10: 10380.04 | U10: 10292.41 | V10: 국고채 | W10: 1010000 | X10: 4.3087 | Y10: 4.3302 | Z10: KR103501G935*058
A11: 국고02250-2309(18-6) | B11: 43353 | C11: 월 | D11: 45179 | E11: 일 | F11: 0004-00-12 | G11: 7342000 | H11: 7342000 | I11: 이표고정 | J11: 6 | K11: 2.25 | L11: - | M11: - | N11: X | O11: 무보증 | P11: 상장 | Q11: 공모직접 | R11: 선 | S11: 1.215 | T11: 10511.24 | U11: 10406.08 | V11: 국고채 | W11: 1010000 | X11: 3.8211 | Y11: 3.8427 | Z11: KR103501G893*058
A12: 국고02375-2303(18-1) | B12: 43169 | C12: 토 | D12: 44995 | E12: 금 | F12: 0003-06-10 | G12: 12566000 | H12: 12566000 | I12: 이표고정 | J12: 6 | K12: 2.375 | L12: - | M12: - | N12: X | O12: 무보증 | P12: 상장 | Q12: 공모직접 | R12: 선 | S12: 1.213 | T12: 10511.59 | U12: 10400.95 | V12: 국고채 | W12: 1010000 | X12: 3.3572 | Y12: 3.3727 | Z12: KR103501G836*058
A13: 국고02000-2209(17-4) | B13: 42988 | C13: 일 | D13: 44814 | E13: 토 | F13: 0003-00-12 | G13: 9626000 | H13: 9626000 | I13: 이표고정 | J13: 6 | K13: 2 | L13: - | M13: - | N13: X | O13: 무보증 | P13: 상장 | Q13: 공모직접 | R13: 선 | S13: 1.21 | T13: 10327.98 | U13: 10234.51 | V13: 국고채 | W13: 1010000 | X13: 2.9152 | Y13: 2.9321 | Z13: KR103501G794*058
A14: 국고01875-2203(16-10) | B14: 42804 | C14: 금 | D14: 44630 | E14: 목 | F14: 0002-06-10 | G14: 13790000 | H14: 13346000 | I14: 이표고정 | J14: 6 | K14: 1.875 | L14: - | M14: - | N14: X | O14: 무보증 | P14: 상장 | Q14: 공모직접 | R14: 선 | S14: 1.205 | T14: 10254.06 | U14: 10166.1 | V14: 국고채 | W14: 1010000 | X14: 2.4504 | Y14: 2.4608 | Z14: KR103501G737*058
A15: 국고01375-2109(16-4) | B15: 42623 | C15: 토 | D15: 44449 | E15: 금 | F15: 0002-00-12 | G15: 10077000 | H15: 9553000 | I15: 이표고정 | J15: 6 | K15: 1.375 | L15: - | M15: - | N15: X | O15: 무보증 | P15: 상장 | Q15: 공모직접 | R15: 선 | S15: 1.201 | T15: 10099 | U15: 10034.61 | V15: 국고채 | W15: 1010000 | X15: 1.9872 | Y15: 1.999 | Z15: KR103501G695*058
A16: 국고02000-2103(15-9) | B16: 42439 | C16: 목 | D16: 44265 | E16: 수 | F16: 0001-06-10 | G16: 14366000 | H16: 12879000 | I16: 이표고정 | J16: 6 | K16: 2 | L16: - | M16: - | N16: X | O16: 무보증 | P16: 상장 | Q16: 공모직접 | R16: 선 | S16: 1.16 | T16: 10220.58 | U16: 10127.21 | V16: 국고채 | W16: 1010000 | X16: 1.495 | Y16: 1.4996 | Z16: KR103501G638*058
A17: 국고02000-2009(15-4) | B17: 42257 | C17: 목 | D17: 44084 | E17: 목 | F17: 0001-00-12 | G17: 15238000 | H17: 12033000 | I17: 이표고정 | J17: 6 | K17: 2 | L17: - | M17: - | N17: X | O17: 무보증 | P17: 상장 | Q17: 공모직접 | R17: 선 | S17: 1.155 | T17: 10179.86 | U17: 10086.46 | V17: 국고채 | W17: 1010000 | X17: 1.0122 | Y17: 1.0181 | Z17: KR103501G596*058
A18: 국고02000-2003(15-1) | B18: 42073 | C18: 화 | D18: 43900 | E18: 화 | F18: 0000-06-10 | G18: 12584000 | H18: 7717000 | I18: 이표고정 | J18: 6 | K18: 2 | L18: - | M18: - | N18: X | O18: 무보증 | P18: 상장 | Q18: 공모직접 | R18: 선 | S18: 1.158 | T18: 10137.99 | U18: 10044.61 | V18: 국고채 | W18: 1010000 | X18: 0.5248 | Y18: 0.5251 | Z18: KR103501G539*058
A19: 국고02750-1909(14-4) | B19: 41892 | C19: 수 | D19: 43718 | E19: 화 | F19: 0000-00-12 | G19: 11564000 | H19: 8734000 | I19: 이표고정 | J19: 6 | K19: 2.75 | L19: - | M19: - | N19: X | O19: 무보증 | P19: 상장 | Q19: 공모직접 | R19: 선 | S19: 1.245 | T19: 10133.37 | U19: 10004.83 | V19: 국고채 | W19: 1010000 | X19: 0.0325 | Y19: 0.0327 | Z19: KR103501G497*058
A20: - | B20: - | D20: - | F20: - | G20: - | H20: - | I20: - | J20: - | K20: 3.125 | L20: - | M20: - | N20: X | O20: - | P20: 비상장 | Q20: - | R20: - | S20: - | T20: - | V20: - | W20: - | X20: - | Y20: - | Z20: -
A21: 국고01875-2906(19-4) | B21: 43626 | C21: 월 | D21: 47279 | E21: 일 | F21: 0009-09-12 | G21: 8343000 | H21: 8343000 | I21: 이표고정 | J21: 6 | K21: 1.875 | L21: - | M21: - | N21: X | O21: 무보증 | P21: 상장 | Q21: 공모직접 | R21: 선 | S21: 1.241 | T21: 10622.82 | U21: 10581.21 | V21: 국고채 | W21: 1010000 | X21: 8.937 | Y21: 8.9755 | Z21: KR103502G966*058
A22: 국고02375-2812(18-10) | B22: 43444 | C22: 월 | D22: 47097 | E22: 일 | F22: 0009-03-11 | G22: 11424000 | H22: 11424000 | I22: 이표고정 | J22: 6 | K22: 2.375 | L22: - | M22: - | N22: X | O22: 무보증 | P22: 상장 | Q22: 공모직접 | R22: 선 | S22: 1.25 | T22: 11034.74 | U22: 10982.83 | V22: 국고채 | W22: 1010000 | X22: 8.3577 | Y22: 8.3966 | Z22: KR103502G8C0*058
A23: 국고02625-2806(18-4) | B23: 43261 | C23: 일 | D23: 46914 | E23: 토 | F23: 0008-09-12 | G23: 11437000 | H23: 11437000 | I23: 이표고정 | J23: 6 | K23: 2.625 | L23: - | M23: - | N23: X | O23: 무보증 | P23: 상장 | Q23: 공모직접 | R23: 선 | S23: 1.25 | T23: 11197.39 | U23: 11140.02 | V23: 국고채 | W23: 1010000 | X23: 7.8795 | Y23: 7.9168 | Z23: KR103502G867*058
A24: 국고02375-2712(17-7) | B24: 43079 | C24: 일 | D24: 46731 | E24: 금 | F24: 0008-03-11 | G24: 11903000 | H24: 11903000 | I24: 이표고정 | J24: 6 | K24: 2.375 | L24: - | M24: - | N24: X | O24: 무보증 | P24: 상장 | Q24: 공모직접 | R24: 선 | S24: 1.246 | T24: 10937.22 | U24: 10884.77 | V24: 국고채 | W24: 1010000 | X24: 7.5315 | Y24: 7.568 | Z24: KR103502G7C2*058
A25: 국고02125-2706(17-3) | B25: 42896 | C25: 토 | D25: 46548 | E25: 목 | F25: 0007-09-12 | G25: 12572000 | H25: 12572000 | I25: 이표고정 | J25: 6 | K25: 2.125 | L25: - | M25: - | N25: X | O25: 무보증 | P25: 상장 | Q25: 공모직접 | R25: 선 | S25: 1.241 | T25: 10699.83 | U25: 10652.88 | V25: 국고채 | W25: 1010000 | X25: 7.169 | Y25: 7.2039 | Z25: KR103502G768*058
A26: 국고01500-2612(16-8) | B26: 42714 | C26: 토 | D26: 46366 | E26: 목 | F26: 0007-03-11 | G26: 13063000 | H26: 13063000 | I26: 이표고정 | J26: 6 | K26: 1.5 | L26: - | M26: - | N26: X | O26: 무보증 | P26: 상장 | Q26: 공모직접 | R26: 선 | S26: 1.237 | T26: 10215.03 | U26: 10180.38 | V26: 국고채 | W26: 1010000 | X26: 6.8727 | Y26: 6.908 | Z26: KR103502G6C4*058
A27: 국고01875-2606(16-3) | B27: 42531 | C27: 금 | D27: 46183 | E27: 수 | F27: 0006-09-12 | G27: 12250000 | H27: 12212000 | I27: 이표고정 | J27: 6 | K27: 1.875 | L27: - | M27: - | N27: X | O27: 무보증 | P27: 상장 | Q27: 공모직접 | R27: 선 | S27: 1.235 | T27: 10455.52 | U27: 10411.67 | V27: 국고채 | W27: 1010000 | X27: 6.3519 | Y27: 6.3841 | Z27: KR103502G669*058
A28: 국고02250-2512(15-8) | B28: 42348 | C28: 목 | D28: 46001 | E28: 수 | F28: 0006-03-11 | G28: 13030012 | H28: 12790012 | I28: 이표고정 | J28: 6 | K28: 2.25 | L28: - | M28: - | N28: X | O28: 무보증 | P28: 상장 | Q28: 공모직접 | R28: 선 | S28: 1.229 | T28: 10664.42 | U28: 10614.62 | V28: 국고채 | W28: 1010000 | X28: 5.8498 | Y28: 5.8811 | Z28: KR103502G5C6*058
A29: 국고02250-2506(15-2) | B29: 42165 | C29: 수 | D29: 45818 | E29: 화 | F29: 0005-09-12 | G29: 15232000 | H29: 15028000 | I29: 이표고정 | J29: 6 | K29: 2.25 | L29: - | M29: - | N29: X | O29: 무보증 | P29: 상장 | Q29: 공모직접 | R29: 선 | S29: 1.224 | T29: 10619.65 | U29: 10569.13 | V29: 국고채 | W29: 1010000 | X29: 5.4113 | Y29: 5.4394 | Z29: KR103501G562*058
A30: 국고03000-2409(14-5) | B30: 41892 | C30: 수 | D30: 45545 | E30: 화 | F30: 0005-00-12 | G30: 16621030 | H30: 16366030 | I30: 이표고정 | J30: 6 | K30: 3 | L30: - | M30: - | N30: X | O30: 무보증 | P30: 상장 | Q30: 공모직접 | R30: 선 | S30: 1.222 | T30: 11005.28 | U30: 10865.24 | V30: 국고채 | W30: 1010000 | X30: 4.639 | Y30: 4.6647 | Z30: KR103502G495*058
A31: 국고03500-2403(14-2) | B31: 41708 | C31: 월 | D31: 45361 | E31: 일 | F31: 0004-06-10 | G31: 13194001 | H31: 13194001 | I31: 이표고정 | J31: 6 | K31: 3.5 | L31: - | M31: - | N31: X | O31: 무보증 | P31: 상장 | Q31: 공모직접 | R31: 선 | S31: 1.222 | T31: 11164.86 | U31: 11000.04 | V31: 국고채 | W31: 1010000 | X31: 4.1623 | Y31: 4.1833 | Z31: KR103502G438*058
A32: 국고03375-2309(13-6) | B32: 41527 | C32: 화 | D32: 45179 | E32: 일 | F32: 0004-00-12 | G32: 12430026 | H32: 12430026 | I32: 이표고정 | J32: 6 | K32: 3.375 | L32: - | M32: - | N32: X | O32: 무보증 | P32: 상장 | Q32: 공모직접 | R32: 선 | S32: 1.215 | T32: 11004.96 | U32: 10847.5 | V32: 국고채 | W32: 1010000 | X32: 3.7394 | Y32: 3.7605 | Z32: KR103502G396*058
... A105: 통안DC019-0903-0910 | B105: 43620 | C105: 화 | D105: 43711 | E105: 화 | F105: 0000-00-05 | G105: 800000 | H105: 800000 | I105: 할인 | J105: 12 | K105: 1.614 | L105: - | M105: - | N105: X | O105: 무보증 | P105: 상장 | Q105: 공모직접 | R105: 선 | S105: 1.275 | T105: 9998.25 | U105: 9998.24 | V105: 통안채 | W105: 4000000 | X105: 0.0136 | Y105: 0.0136 | Z105: KR310102A967*058

Sheet 1(t-1)
A1: 종목명 | B1: 발행일 | C1: 일 | D1: 만기일 | E1: 일 | F1: 잔존일 | G1: 발행액(백만) | H1: 상장잔액(백만) | I1: 이자유형 | J1: 주기 | K1: 표면금리 | L1: 주식옵션 | M1: 중도상환 | N1: ABS | O1: 보증유형 | P1: 상장여부 | Q1: 공사모 | R1: 순위 | S1: 민평3사 | T1: 시가 | U1: C.가격 | V1: 신용그룹 | W1: 신용그룹코드 | X1: PPC100 | Y1: 듀레이션 | Z1: 표준코드
A2: 국고01625-2206(19-3) | B2: 43626 | C2: 월 | D2: 44722 | E2: 금 | F2: 0002-09-13 | G2: 7990000 | H2: 7990000 | I2: 이표고정 | J2: 6 | K2: 1.625 | L2: - | M2: - | N2: X | O2: 무보증 | P2: 상장 | Q2: 공모직접 | R2: 선 | S2: 1.177 | T2: 10157.32 | U2: 10122.25 | V2: 국고채 | W2: 1010000 | X2: 2.7101 | Y2: 2.7242 | Z2: KR103501G968*058
A3: 국고02000-2112(18-9) | B3: 43444 | C3: 월 | D3: 44540 | E3: 금 | F3: 0002-03-12 | G3: 9943000 | H3: 9943000 | I3: 이표고정 | J3: 6 | K3: 2 | L3: - | M3: - | N3: X | O3: 무보증 | P3: 상장 | Q3: 공모직접 | R3: 선 | S3: 1.205 | T3: 10221.63 | U3: 10178.47 | V3: 국고채 | W3: 1010000 | X3: 2.2233 | Y3: 2.2364 | Z3: KR103501G8C1*058
A4: 국고02250-2106(18-3) | B4: 43261 | C4: 일 | D4: 44357 | E4: 목 | F4: 0001-09-13 | G4: 9469000 | H4: 9469000 | I4: 이표고정 | J4: 6 | K4: 2.25 | L4: - | M4: - | N4: X | O4: 무보증 | P4: 상장 | Q4: 공모직접 | R4: 선 | S4: 1.204 | T4: 10232.51 | U4: 10183.78 | V4: 국고채 | W4: 1010000 | X4: 1.7418 | Y4: 1.7508 | Z4: KR103501G869*058
A5: 국고01750-2012(17-6) | B5: 43079 | C5: 일 | D5: 44175 | E5: 목 | F5: 0001-03-12 | G5: 10705000 | H5: 10595000 | I5: 이표고정 | J5: 6 | K5: 1.75 | L5: - | M5: - | N5: X | O5: 무보증 | P5: 상장 | Q5: 공모직접 | R5: 선 | S5: 1.151 | T5: 10113.71 | U5: 10076.16 | V5: 국고채 | W5: 1010000 | X5: 1.2647 | Y5: 1.272 | Z5: KR103501G7C3*058
A6: 국고01750-2006(17-2) | B6: 42896 | C6: 토 | D6: 43992 | E6: 수 | F6: 0000-09-13 | G6: 9423000 | H6: 7539000 | I6: 이표고정 | J6: 6 | K6: 1.75 | L6: - | M6: - | N6: X | O6: 무보증 | P6: 상장 | Q6: 공모직접 | R6: 선 | S6: 1.125 | T6: 10086.33 | U6: 10049.34 | V6: 국고채 | W6: 1010000 | X6: 0.7761 | Y6: 0.7798 | Z6: KR103501G760*058
A7: 국고01250-1912(16-7) | B7: 42714 | C7: 토 | D7: 43809 | E7: 화 | F7: 0000-03-12 | G7: 11710000 | H7: 6599000 | I7: 이표고정 | J7: 6 | K7: 1.25 | L7: - | M7: - | N7: X | O7: 무보증 | P7: 상장 | Q7: 공모직접 | R7: 선 | S7: 1.206 | T7: 10028.11 | U7: 10001.32 | V7: 국고채 | W7: 1010000 | X7: 0.2831 | Y7: 0.2841 | Z7: KR103501G6C5*058
A8: - | B8: - | D8: - | F8: - | G8: - | H8: - | I8: - | J8: - | K8: 1.5 | L8: - | M8: - | N8: X | O8: - | P8: 비상장 | Q8: - | R8: - | S8: - | T8: - | V8: - | W8: - | X8: - | Y8: - | Z8: -
A9: 국고01375-2409(19-5) | B9: 43718 | C9: 화 | D9: 45545 | E9: 화 | F9: 0005-00-13 | G9: 1234000 | H9: 1234000 | I9: 이표고정 | J9: 6 | K9: 1.375 | L9: - | M9: - | N9: X | O9: 무보증 | P9: 상장 | Q9: 공모직접 | R9: 선 | S9: 1.191 | T9: 10084.64 | U9: 10084.32 | V9: 국고채 | W9: 1010000 | X9: 4.8591 | Y9: 4.8854 | Z9: KR103501G992*058
A10: 국고01875-2403(19-1) | B10: 43534 | C10: 일 | D10: 45361 | E10: 일 | F10: 0004-06-11 | G10: 10675000 | H10: 10675000 | I10: 이표고정 | J10: 6 | K10: 1.875 | L10: - | M10: - | N10: X | O10: 무보증 | P10: 상장 | Q10: 공모직접 | R10: 선 | S10: 1.21 | T10: 10379.7 | U10: 10292.58 | V10: 국고채 | W10: 1010000 | X10: 4.3114 | Y10: 4.3329 | Z10: KR103501G935*058
A11: 국고02250-2309(18-6) | B11: 43353 | C11: 월 | D11: 45179 | E11: 일 | F11: 0004-00-13 | G11: 7342000 | H11: 7342000 | I11: 이표고정 | J11: 6 | K11: 2.25 | L11: - | M11: - | N11: X | O11: 무보증 | P11: 상장 | Q11: 공모직접 | R11: 선 | S11: 1.217 | T11: 10510.09 | U11: 10405.54 | V11: 국고채 | W11: 1010000 | X11: 3.8237 | Y11: 3.8454 | Z11: KR103501G893*058
A12: 국고02375-2303(18-1) | B12: 43169 | C12: 토 | D12: 44995 | E12: 금 | F12: 0003-06-10 | G12: 12566000 | H12: 12566000 | I12: 이표고정 | J12: 6 | K12: 2.375 | L12: - | M12: - | N12: X | O12: 무보증 | P12: 상장 | Q12: 공모직접 | R12: 선 | S12: 1.216 | T12: 10510.07 | U12: 10400.19 | V12: 국고채 | W12: 1010000 | X12: 3.3598 | Y12: 3.3754 | Z12: KR103501G836*058
A13: 국고02000-2209(17-4) | B13: 42988 | C13: 일 | D13: 44814 | E13: 토 | F13: 0003-00-13 | G13: 9626000 | H13: 9626000 | I13: 이표고정 | J13: 6 | K13: 2 | L13: - | M13: - | N13: X | O13: 무보증 | P13: 상장 | Q13: 공모직접 | R13: 선 | S13: 1.214 | T13: 10326.44 | U13: 10233.21 | V13: 국고채 | W13: 1010000 | X13: 2.9178 | Y13: 2.9348 | Z13: KR103501G794*058
A14: 국고01875-2203(16-10) | B14: 42804 | C14: 금 | D14: 44630 | E14: 목 | F14: 0002-06-10 | G14: 13790000 | H14: 13346000 | I14: 이표고정 | J14: 6 | K14: 1.875 | L14: - | M14: - | N14: X | O14: 무보증 | P14: 상장 | Q14: 공모직접 | R14: 선 | S14: 1.21 | T14: 10252.64 | U14: 10165.52 | V14: 국고채 | W14: 1010000 | X14: 2.4531 | Y14: 2.4636 | Z14: KR103501G737*058
A15: 국고01375-2109(16-4) | B15: 42623 | C15: 토 | D15: 44449 | E15: 금 | F15: 0002-00-13 | G15: 10077000 | H15: 9553000 | I15: 이표고정 | J15: 6 | K15: 1.375 | L15: - | M15: - | N15: X | O15: 무보증 | P15: 상장 | Q15: 공모직접 | R15: 선 | S15: 1.205 | T15: 10097.94 | U15: 10034.05 | V15: 국고채 | W15: 1010000 | X15: 1.9899 | Y15: 2.0017 | Z15: KR103501G695*058
A16: 국고02000-2103(15-9) | B16: 42439 | C16: 목 | D16: 44265 | E16: 수 | F16: 0001-06-10 | G16: 14366000 | H16: 12879000 | I16: 이표고정 | J16: 6 | K16: 2 | L16: - | M16: - | N16: X | O16: 무보증 | P16: 상장 | Q16: 공모직접 | R16: 선 | S16: 1.159 | T16: 10220.51 | U16: 10127.43 | V16: 국고채 | W16: 1010000 | X16: 1.4977 | Y16: 1.5023 | Z16: KR103501G638*058
A17: 국고02000-2009(15-4) | B17: 42257 | C17: 목 | D17: 44084 | E17: 목 | F17: 0001-00-13 | G17: 15238000 | H17: 12033000 | I17: 이표고정 | J17: 6 | K17: 2 | L17: - | M17: - | N17: X | O17: 무보증 | P17: 상장 | Q17: 공모직접 | R17: 선 | S17: 1.149 | T17: 10180.16 | U17: 10087.2 | V17: 국고채 | W17: 1010000 | X17: 1.015 | Y17: 1.0208 | Z17: KR103501G596*058
A18: 국고02000-2003(15-1) | B18: 42073 | C18: 화 | D18: 43900 | E18: 화 | F18: 0000-06-11 | G18: 12584000 | H18: 7717000 | I18: 이표고정 | J18: 6 | K18: 2 | L18: - | M18: - | N18: X | O18: 무보증 | P18: 상장 | Q18: 공모직접 | R18: 선 | S18: 1.158 | T18: 10137.67 | U18: 10044.83 | V18: 국고채 | W18: 1010000 | X18: 0.5275 | Y18: 0.5278 | Z18: KR103501G539*058
A19: 국고02750-1909(14-4) | B19: 41892 | C19: 수 | D19: 43718 | E19: 화 | F19: 0000-00-13 | G19: 11564000 | H19: 8734000 | I19: 이표고정 | J19: 6 | K19: 2.75 | L19: - | M19: - | N19: X | O19: 무보증 | P19: 상장 | Q19: 공모직접 | R19: 선 | S19: 1.249 | T19: 10133.02 | U19: 10005.24 | V19: 국고채 | W19: 1010000 | X19: 0.0353 | Y19: 0.0355 | Z19: KR103501G497*058
A20: - | B20: - | D20: - | F20: - | G20: - | H20: - | I20: - | J20: - | K20: 3.125 | L20: - | M20: - | N20: X | O20: - | P20: 비상장 | Q20: - | R20: - | S20: - | T20: - | V20: - | W20: - | X20: - | Y20: - | Z20: -
A21: 국고01875-2906(19-4) | B21: 43626 | C21: 월 | D21: 47279 | E21: 일 | F21: 0009-09-13 | G21: 8343000 | H21: 8343000 | I21: 이표고정 | J21: 6 | K21: 1.875 | L21: - | M21: - | N21: X | O21: 무보증 | P21: 상장 | Q21: 공모직접 | R21: 선 | S21: 1.25 | T21: 10614.25 | U21: 10573.78 | V21: 국고채 | W21: 1010000 | X21: 8.9389 | Y21: 8.9779 | Z21: KR103502G966*058
A22: 국고02375-2812(18-10) | B22: 43444 | C22: 월 | D22: 47097 | E22: 일 | F22: 0009-03-12 | G22: 11424000 | H22: 11424000 | I22: 이표고정 | J22: 6 | K22: 2.375 | L22: - | M22: - | N22: X | O22: 무보증 | P22: 상장 | Q22: 공모직접 | R22: 선 | S22: 1.26 | T22: 11025.15 | U22: 10973.89 | V22: 국고채 | W22: 1010000 | X22: 8.3595 | Y22: 8.3989 | Z22: KR103502G8C0*058
A23: 국고02625-2806(18-4) | B23: 43261 | C23: 일 | D23: 46914 | E23: 토 | F23: 0008-09-13 | G23: 11437000 | H23: 11437000 | I23: 이표고정 | J23: 6 | K23: 2.625 | L23: - | M23: - | N23: X | O23: 무보증 | P23: 상장 | Q23: 공모직접 | R23: 선 | S23: 1.26 | T23: 11188.2 | U23: 11131.55 | V23: 국고채 | W23: 1010000 | X23: 7.8814 | Y23: 7.9191 | Z23: KR103502G867*058
A24: 국고02375-2712(17-7) | B24: 43079 | C24: 일 | D24: 46731 | E24: 금 | F24: 0008-03-12 | G24: 11903000 | H24: 11903000 | I24: 이표고정 | J24: 6 | K24: 2.375 | L24: - | M24: - | N24: X | O24: 무보증 | P24: 상장 | Q24: 공모직접 | R24: 선 | S24: 1.256 | T24: 10928.62 | U24: 10876.82 | V24: 국고채 | W24: 1010000 | X24: 7.5335 | Y24: 7.5704 | Z24: KR103502G7C2*058
A25: 국고02125-2706(17-3) | B25: 42896 | C25: 토 | D25: 46548 | E25: 목 | F25: 0007-09-13 | G25: 12572000 | H25: 12572000 | I25: 이표고정 | J25: 6 | K25: 2.125 | L25: - | M25: - | N25: X | O25: 무보증 | P25: 상장 | Q25: 공모직접 | R25: 선 | S25: 1.249 | T25: 10693.08 | U25: 10649.27 | V25: 국고채 | W25: 1010000 | X25: 7.1712 | Y25: 7.2064 | Z25: KR103502G768*058
A26: 국고01500-2612(16-8) | B26: 42714 | C26: 토 | D26: 46366 | E26: 목 | F26: 0007-03-12 | G26: 13063000 | H26: 13063000 | I26: 이표고정 | J26: 6 | K26: 1.5 | L26: - | M26: - | N26: X | O26: 무보증 | P26: 상장 | Q26: 공모직접 | R26: 선 | S26: 1.244 | T26: 10209.54 | U26: 10176.94 | V26: 국고채 | W26: 1010000 | X26: 6.875 | Y26: 6.9106 | Z26: KR103502G6C4*058
A27: 국고01875-2606(16-3) | B27: 42531 | C27: 금 | D27: 46183 | E27: 수 | F27: 0006-09-13 | G27: 12250000 | H27: 12212000 | I27: 이표고정 | J27: 6 | K27: 1.875 | L27: - | M27: - | N27: X | O27: 무보증 | P27: 상장 | Q27: 공모직접 | R27: 선 | S27: 1.243 | T27: 10450.08 | U27: 10408.51 | V27: 국고채 | W27: 1010000 | X27: 6.3543 | Y27: 6.3867 | Z27: KR103502G669*058
A28: 국고02250-2512(15-8) | B28: 42348 | C28: 목 | D28: 46001 | E28: 수 | F28: 0006-03-12 | G28: 13030012 | H28: 12790012 | I28: 이표고정 | J28: 6 | K28: 2.25 | L28: - | M28: - | N28: X | O28: 무보증 | P28: 상장 | Q28: 공모직접 | R28: 선 | S28: 1.235 | T28: 10659.91 | U28: 10611.77 | V28: 국고채 | W28: 1010000 | X28: 5.8523 | Y28: 5.8838 | Z28: KR103502G5C6*058
A29: 국고02250-2506(15-2) | B29: 42165 | C29: 수 | D29: 45818 | E29: 화 | F29: 0005-09-13 | G29: 15232000 | H29: 15028000 | I29: 이표고정 | J29: 6 | K29: 2.25 | L29: - | M29: - | N29: X | O29: 무보증 | P29: 상장 | Q29: 공모직접 | R29: 선 | S29: 1.23 | T29: 10615.84 | U29: 10567.67 | V29: 국고채 | W29: 1010000 | X29: 5.4138 | Y29: 5.4421 | Z29: KR103501G562*058
A30: 국고03000-2409(14-5) | B30: 41892 | C30: 수 | D30: 45545 | E30: 화 | F30: 0005-00-13 | G30: 16621030 | H30: 16366030 | I30: 이표고정 | J30: 6 | K30: 3 | L30: - | M30: - | N30: X | O30: 무보증 | P30: 상장 | Q30: 공모직접 | R30: 선 | S30: 1.225 | T30: 11003.21 | U30: 10866.71 | V30: 국고채 | W30: 1010000 | X30: 4.6416 | Y30: 4.6674 | Z30: KR103502G495*058
A31: 국고03500-2403(14-2) | B31: 41708 | C31: 월 | D31: 45361 | E31: 일 | F31: 0004-06-11 | G31: 13194001 | H31: 13194001 | I31: 이표고정 | J31: 6 | K31: 3.5 | L31: - | M31: - | N31: X | O31: 무보증 | P31: 상장 | Q31: 공모직접 | R31: 선 | S31: 1.225 | T31: 11163.25 | U31: 11000.62 | V31: 국고채 | W31: 1010000 | X31: 4.1649 | Y31: 4.186 | Z31: KR103502G438*058
A32: 국고03375-2309(13-6) | B32: 41527 | C32: 화 | D32: 45179 | E32: 일 | F32: 0004-00-13 | G32: 12430026 | H32: 12430026 | I32: 이표고정 | J32: 6 | K32: 3.375 | L32: - | M32: - | N32: X | O32: 무보증 | P32: 상장 | Q32: 공모직접 | R32: 선 | S32: 1.218 | T32: 11003.63 | U32: 10847.23 | V32: 국고채 | W32: 1010000 | X32: 3.742 | Y32: 3.7632 | Z32: KR103502G396*058
... A105: 통안DC019-0903-0910 | B105: 43620 | C105: 화 | D105: 43711 | E105: 화 | F105: 0000-00-06 | G105: 800000 | H105: 800000 | I105: 할인 | J105: 12 | K105: 1.614 | L105: - | M105: - | N105: X | O105: 무보증 | P105: 상장 | Q105: 공모직접 | R105: 선 | S105: 1.275 | T105: 9997.9 | U105: 9997.89 | V105: 통안채 | W105: 4000000 | X105: 0.0164 | Y105: 0.0163 | Z105: KR310102A967*058

Sheet 2
A1: 종목명 | B1: 발행일 | C1: 일 | D1: 만기일 | E1: 일 | F1: 잔존일 | G1: 발행액(백만) | H1: 상장잔액(백만) | I1: 이자유형 | J1: 주기 | K1: 표면금리 | L1: 주식옵션 | M1: 중도상환 | N1: ABS | O1: 보증유형 | P1: 상장여부 | Q1: 공사모 | R1: 순위 | S1: 민평3사 | T1: 시가 | U1: C.가격 | V1: 신용그룹 | W1: 신용그룹코드 | X1: PPC100 | Y1: 듀레이션 | Z1: 표준코드
A2: 국민주택1종19-08-2 | B2: 43708 | C2: 토 | D2: 45535 | E2: 토 | F2: 0005-00-02 | G2: 1008781 | H2: 1008781 | I2: 복리 | J2: 12 | K2: 1 | L2: - | M2: - | N2: X | O2: 무보증 | P2: 상장 | Q2: 공모직접 | R2: 선 | S2: 1.275 | T2: 9864.18 | U2: 9864.18 | V2: 국민주택 1종 | W2: 1020000 | X2: 4.9459 | Y2: 5.0054 | Z2: KR101502D981*058
A3: 국민주택1종19-08 | B3: 43708 | C3: 토 | D3: 45535 | E3: 토 | F3: 0005-00-02 | G3: 493819 | H3: 493819 | I3: 복리 | J3: 12 | K3: 1.25 | L3: - | M3: - | N3: X | O3: 무보증 | P3: 상장 | Q3: 공모직접 | R3: 선 | S3: 1.275 | T3: 9986.19 | U3: 9986.19 | V3: 국민주택 1종 | W3: 1020000 | X3: 4.9459 | Y3: 5.0054 | Z3: KR101501D983*058
A4: 국민주택1종19-07-2 | B4: 43677 | C4: 수 | D4: 45504 | E4: 수 | F4: 0004-11-02 | G4: 430893 | H4: 430790 | I4: 복리 | J4: 12 | K4: 1.25 | L4: - | M4: - | N4: X | O4: 무보증 | P4: 상장 | Q4: 공모직접 | R4: 선 | S4: 1.275 | T4: 9996.7 | U4: 9987.02 | V4: 국민주택 1종 | W4: 1020000 | X4: 4.8629 | Y4: 4.9207 | Z4: KR101502D973*058
A5: 국민주택1종19-07 | B5: 43677 | C5: 수 | D5: 45504 | E5: 수 | F5: 0004-11-02 | G5: 1037399 | H5: 1036789 | I5: 복리 | J5: 12 | K5: 1.5 | L5: - | M5: - | N5: X | O5: 무보증 | P5: 상장 | Q5: 공모직접 | R5: 선 | S5: 1.275 | T5: 10120.71 | U5: 10109.08 | V5: 국민주택 1종 | W5: 1020000 | X5: 4.8629 | Y5: 4.9207 | Z5: KR101501D975*058
A6: 국민주택1종19-06-2 | B6: 43646 | C6: 일 | D6: 45473 | E6: 일 | F6: 0004-10-01 | G6: 1063638 | H6: 1062981 | I6: 복리 | J6: 12 | K6: 1.5 | L6: - | M6: - | N6: X | O6: 무보증 | P6: 상장 | Q6: 공모직접 | R6: 선 | S6: 1.273 | T6: 10132.66 | U6: 10108.23 | V6: 국민주택 1종 | W6: 1020000 | X6: 4.78 | Y6: 4.836 | Z6: KR101502D965*058
A7: 국민주택1종19-06 | B7: 43646 | C7: 일 | D7: 45473 | E7: 일 | F7: 0004-10-01 | G7: 79026 | H7: 78726 | I7: 복리 | J7: 12 | K7: 1.75 | L7: - | M7: - | N7: X | O7: 무보증 | P7: 상장 | Q7: 공모직접 | R7: 선 | S7: 1.273 | T7: 10258.71 | U7: 10230.23 | V7: 국민주택 1종 | W7: 1020000 | X7: 4.78 | Y7: 4.836 | Z7: KR101501D967*058
A8: 국민주택1종19-05 | B8: 43616 | C8: 금 | D8: 45443 | E8: 금 | F8: 0004-09-02 | G8: 1323766 | H8: 1322205 | I8: 복리 | J8: 12 | K8: 1.75 | L8: - | M8: - | N8: X | O8: 무보증 | P8: 상장 | Q8: 공모직접 | R8: 선 | S8: 1.272 | T8: 10269.63 | U8: 10227.05 | V8: 국민주택 1종 | W8: 1020000 | X8: 4.6996 | Y8: 4.754 | Z8: KR101501D959*058
A9: 경기지역개발19-08 | B9: 43708 | C9: 토 | D9: 45535 | E9: 토 | F9: 0005-00-02 | G9: 25635 | H9: 25635 | I9: 복리 | J9: 12 | K9: 1.25 | L9: - | M9: - | N9: X | O9: 무보증 | P9: 상장 | Q9: 공모직접 | R9: 선 | S9: 1.324 | T9: 9962.13 | U9: 9961.55 | V9: 경기지방채 | W9: 2045000 | X9: 4.9435 | Y9: 5.0054 | Z9: KR2044012988*058
A10: 경기지역개발19-07 | B10: 43677 | C10: 수 | D10: 45504 | E10: 수 | F10: 0004-11-02 | G10: 29005 | H10: 29005 | I10: 복리 | J10: 12 | K10: 1.25 | L10: - | M10: - | N10: X | O10: 무보증 | P10: 상장 | Q10: 공모직접 | R10: 선 | S10: 1.323 | T10: 9973.5 | U10: 9962.76 | V10: 경기지방채 | W10: 2045000 | X10: 4.8606 | Y10: 4.9207 | Z10: KR2044012970*058
A11: 경기지역개발19-06 | B11: 43646 | C11: 일 | D11: 45473 | E11: 일 | F11: 0004-10-01 | G11: 24093 | H11: 24093 | I11: 복리 | J11: 12 | K11: 1.25 | L11: - | M11: - | N11: X | O11: 무보증 | P11: 상장 | Q11: 공모직접 | R11: 선 | S11: 1.322 | T11: 9985.2 | U11: 9964.25 | V11: 경기지방채 | W11: 2045000 | X11: 4.7777 | Y11: 4.836 | Z11: KR2044012962*058
A12: 예보상환기금채2018-2 | B12: 43322 | C12: 금 | D12: 44418 | E12: 화 | F12: 0001-11-12 | G12: 800000 | H12: 800000 | I12: 이표고정 | J12: 6 | K12: 2.15 | L12: - | M12: - | N12: X | O12: 정부보증 | P12: 상장 | Q12: 공모직접 | R12: 선 | S12: 1.312 | T12: 10171.66 | U12: 10162.18 | V12: 정부보증채 | W12: 3030000 | X12: 1.905 | Y12: 1.9166 | Z12: KR352601G881*058
A13: 예보상환기금채2018-1 | B13: 43131 | C13: 수 | D13: 44227 | E13: 일 | F13: 0001-05-02 | G13: 680000 | H13: 680000 | I13: 이표고정 | J13: 6 | K13: 2.52 | L13: - | M13: - | N13: X | O13: 정부보증 | P13: 상장 | Q13: 공모직접 | R13: 선 | S13: 1.284 | T13: 10193.19 | U13: 10174.29 | V13: 정부보증채 | W13: 3030000 | X13: 1.3943 | Y13: 1.4061 | Z13: KR352601G816*058
... A15: 예보상환기금채2015-1 | B15: 42333 | C15: 수 | D15: 44160 | E15: 수 | F15: 0001-02-27 | G15: 880000 | H15: 880000 | I15: 이표고정 | J15: 6 | K15: 2.12 | L15: - | M15: - | N15: X | O15: 정부보증 | P15: 상장 | Q15: 공모직접 | R15: 선 | S15: 1.274 | T15: 10158.76 | U15: 10104.29 | V15: 정부보증채 | W15: 3030000 | X15: 1.2166 | Y15: 1.2254 | Z15: KR352601G5B1*058
A16: - | B16: - | D16: - | F16: - | G16: - | H16: - | I16: - | J16: - | K16: 1.34 | L16: - | M16: - | N16: X | O16: - | P16: 비상장 | Q16: - | R16: - | S16: - | T16: - | V16: - | W16: - | X16: - | Y16: - | Z16: -
A17: - | B17: - | D17: - | F17: - | G17: - | H17: - | I17: - | J17: - | K17: 1.61 | L17: - | M17: - | N17: X | O17: - | P17: 비상장 | Q17: - | R17: - | S17: - | T17: - | V17: - | W17: - | X17: - | Y17: - | Z17: -
A18: - | B18: - | D18: - | F18: - | G18: - | H18: - | I18: - | J18: - | K18: 2.84 | L18: - | M18: - | N18: X | O18: - | P18: 비상장 | Q18: - | R18: - | S18: - | T18: - | V18: - | W18: - | X18: - | Y18: - | Z18: -
A19: - | B19: - | D19: - | F19: - | G19: - | H19: - | I19: - | J19: - | K19: 2.98 | L19: - | M19: - | N19: X | O19: - | P19: 비상장 | Q19: - | R19: - | S19: - | T19: - | V19: - | W19: - | X19: - | Y19: - | Z19: -
A20: - | B20: - | D20: - | F20: - | G20: - | H20: - | I20: - | J20: - | K20: 2.98 | L20: - | M20: - | N20: X | O20: - | P20: 비상장 | Q20: - | R20: - | S20: - | T20: - | V20: - | W20: - | X20: - | Y20: - | Z20: -
A21: - | B21: - | D21: - | F21: - | G21: - | H21: - | I21: - | J21: - | K21: 3.12 | L21: - | M21: - | N21: X | O21: - | P21: 비상장 | Q21: - | R21: - | S21: - | T21: - | V21: - | W21: - | X21: - | Y21: - | Z21: -
A22: - | B22: - | D22: - | F22: - | G22: - | H22: - | I22: - | J22: - | K22: 2.74 | L22: - | M22: - | N22: X | O22: - | P22: 비상장 | Q22: - | R22: - | S22: - | T22: - | V22: - | W22: - | X22: - | Y22: - | Z22: -
A23: - | B23: - | D23: - | F23: - | G23: - | H23: - | I23: - | J23: - | K23: 3.67 | L23: - | M23: - | N23: X | O23: - | P23: 비상장 | Q23: - | R23: - | S23: - | T23: - | V23: - | W23: - | X23: - | Y23: - | Z23: -
A24: - | B24: - | D24: - | F24: - | G24: - | H24: - | I24: - | J24: - | K24: 3.04 | L24: - | M24: - | N24: X | O24: - | P24: 비상장 | Q24: - | R24: - | S24: - | T24: - | V24: - | W24: - | X24: - | Y24: - | Z24: -
A25: - | B25: - | D25: - | F25: - | G25: - | H25: - | I25: - | J25: - | K25: 3.07 | L25: - | M25: - | N25: X | O25: - | P25: 비상장 | Q25: - | R25: - | S25: - | T25: - | V25: - | W25: - | X25: - | Y25: - | Z25: -
A26: - | B26: - | D26: - | F26: - | G26: - | H26: - | I26: - | J26: - | K26: 4.14 | L26: - | M26: - | N26: X | O26: - | P26: 비상장 | Q26: - | R26: - | S26: - | T26: - | V26: - | W26: - | X26: - | Y26: - | Z26: -
A27: - | B27: - | D27: - | F27: - | G27: - | H27: - | I27: - | J27: - | K27: 3.88 | L27: - | M27: - | N27: X | O27: - | P27: 비상장 | Q27: - | R27: - | S27: - | T27: - | V27: - | W27: - | X27: - | Y27: - | Z27: -
A28: 예보기금특별계정채권2019-2 | B28: 43542 | C28: 월 | D28: 45369 | E28: 월 | F28: 0004-06-18 | G28: 360000 | H28: 360000 | I28: 이표고정 | J28: 6 | K28: 1.97 | L28: - | M28: - | N28: X | O28: 무보증 | P28: 상장 | Q28: 공모직접 | R28: 선 | S28: 1.33 | T28: 10369.5 | U28: 10282.76 | V28: 정부보증채 | W28: 3030000 | X28: 4.318 | Y28: 4.3421 | Z28: KR352601G931*058
A29: 예보기금특별계정채권2019-1 | B29: 43479 | C29: 월 | D29: 45305 | E29: 일 | F29: 0004-04-16 | G29: 580000 | H29: 580000 | I29: 이표고정 | J29: 6 | K29: 1.98 | L29: - | M29: - | N29: X | O29: 무보증 | P29: 상장 | Q29: 공모직접 | R29: 선 | S29: 1.33 | T29: 10299.86 | U29: 10276.12 | V29: 정부보증채 | W29: 3030000 | X29: 4.18 | Y29: 4.2074 | Z29: KR352601G915*058
A30: 예보기금특별계정채권2018-1 | B30: 43145 | C30: 수 | D30: 44971 | E30: 화 | F30: 0003-05-16 | G30: 320000 | H30: 320000 | I30: 이표고정 | J30: 6 | K30: 2.78 | L30: - | M30: - | N30: X | O30: 무보증 | P30: 상장 | Q30: 공모간접 | R30: 선 | S30: 1.328 | T30: 10500.38 | U30: 10491.01 | V30: 정부보증채 | W30: 3030000 | X30: 3.3018 | Y30: 3.3261 | Z30: KR352601G824*058
A31: 예보기금특별계정채권2017-4 | B31: 42970 | C31: 수 | D31: 44796 | E31: 화 | F31: 0002-11-25 | G31: 1200000 | H31: 1200000 | I31: 이표고정 | J31: 6 | K31: 2.2 | L31: - | M31: - | N31: X | O31: 무보증 | P31: 상장 | Q31: 공모간접 | R31: 선 | S31: 1.329 | T31: 10257.53 | U31: 10256.32 | V31: 정부보증채 | W31: 3030000 | X31: 2.886 | Y31: 2.9044 | Z31: KR352601G782*058
A32: 예보기금특별계정채권2017-3 | B32: 42900 | C32: 수 | D32: 44726 | E32: 화 | F32: 0002-09-16 | G32: 900000 | H32: 900000 | I32: 이표고정 | J32: 6 | K32: 2.11 | L32: - | M32: - | N32: X | O32: 무보증 | P32: 상장 | Q32: 공모간접 | R32: 선 | S32: 1.327 | T32: 10257.52 | U32: 10215.19 | V32: 정부보증채 | W32: 3030000 | X32: 2.6996 | Y32: 2.7156 | Z32: KR352601G766*058
A33: 예보기금특별계정채권2015-1 | B33: 42025 | C33: 수 | D33: 44582 | E33: 금 | F33: 0002-04-23 | G33: 600000 | H33: 600000 | I33: 이표고정 | J33: 6 | K33: 2.34 | L33: - | M33: - | N33: X | O33: 무보증 | P33: 상장 | Q33: 공모직접 | R33: 선 | S33: 1.329 | T33: 10261.98 | U33: 10237.59 | V33: 정부보증채 | W33: 3030000 | X33: 2.3231 | Y33: 2.3408 | Z33: KR352601G519*058
A34: 예보기금특별계정채권2018-4 | B34: 43334 | C34: 수 | D34: 44430 | E34: 일 | F34: 0001-11-24 | G34: 450000 | H34: 450000 | I34: 이표고정 | J34: 6 | K34: 2.09 | L34: - | M34: - | N34: X | O34: 무보증 | P34: 상장 | Q34: 공모직접 | R34: 선 | S34: 1.344 | T34: 10149.3 | U34: 10146.71 | V34: 정부보증채 | W34: 3030000 | X34: 1.9377 | Y34: 1.9503 | Z34: KR352602G889*058
A35: 예보기금특별계정채권2018-3 | B35: 43248 | C35: 월 | D35: 44344 | E35: 금 | F35: 0001-08-29 | G35: 400000 | H35: 400000 | I35: 이표고정 | J35: 6 | K35: 2.37 | L35: - | M35: - | N35: X | O35: 무보증 | P35: 상장 | Q35: 공모간접 | R35: 선 | S35: 1.331 | T35: 10238.53 | U35: 10180.1 | V35: 정부보증채 | W35: 3030000 | X35: 1.7024 | Y35: 1.7108 | Z35: KR352601G857*058
A36: 예보기금특별계정채권2017-2 | B36: 42872 | C36: 수 | D36: 44333 | E36: 월 | F36: 0001-08-18 | G36: 900000 | H36: 900000 | I36: 이표고정 | J36: 6 | K36: 1.99 | L36: - | M36: - | N36: X | O36: 무보증 | P36: 상장 | Q36: 공모간접 | R36: 선 | S36: 1.329 | T36: 10167.85 | U36: 10112.93 | V36: 정부보증채 | W36: 3030000 | X36: 1.678 | Y36: 1.686 | Z36: KR352601G758*058
A37: 예보기금특별계정채권2018-2 | B37: 43152 | C37: 수 | D37: 44248 | E37: 일 | F37: 0001-05-23 | G37: 280000 | H37: 280000 | I37: 이표고정 | J37: 6 | K37: 2.53 | L37: - | M37: - | N37: X | O37: 무보증 | P37: 상장 | Q37: 공모간접 | R37: 선 | S37: 1.319 | T37: 10182.17 | U37: 10177.41 | V37: 정부보증채 | W37: 3030000 | X37: 1.4504 | Y37: 1.4636 | Z37: KR352602G822*058
A38: 예보기금특별계정채권2017-1 | B38: 42753 | C38: 수 | D38: 44214 | E38: 월 | F38: 0001-04-20 | G38: 440000 | H38: 440000 | I38: 이표고정 | J38: 6 | K38: 1.88 | L38: - | M38: - | N38: X | O38: 무보증 | P38: 상장 | Q38: 공모간접 | R38: 선 | S38: 1.314 | T38: 10098.74 | U38: 10078.21 | V38: 정부보증채 | W38: 3030000 | X38: 1.3637 | Y38: 1.3751 | Z38: KR352601G717*058
A39: 예보기금특별계정채권2017-5 | B39: 43026 | C39: 수 | D39: 44122 | E39: 일 | F39: 0001-01-19 | G39: 290000 | H39: 290000 | I39: 이표고정 | J39: 6 | K39: 2.11 | L39: - | M39: - | N39: X | O39: 무보증 | P39: 상장 | Q39: 공모간접 | R39: 선 | S39: 1.304 | T39: 10167.2 | U39: 10091.32 | V39: 정부보증채 | W39: 3030000 | X39: 1.1145 | Y39: 1.1214 | Z39: KR352601G7A9*058
... A43: 예보기금특별계정채권2016-3 | B43: 42712 | C43: 목 | D43: 43807 | E43: 일 | F43: 0000-03-09 | G43: 600000 | H43: 600000 | I43: 이표고정 | J43: 6 | K43: 1.9 | L43: - | M43: - | N43: X | O43: 무보증 | P43: 상장 | Q43: 공모직접 | R43: 선 | S43: 1.345 | T43: 10057.65 | U43: 10015.33 | V43: 정부보증채 | W43: 3030000 | X43: 0.2749 | Y43: 0.2759 | Z43: KR352601G6C7*058
A44: - | B44: - | D44: - | F44: - | G44: - | H44: - | I44: - | J44: - | K44: 1.63 | L44: - | M44: - | N44: X | O44: - | P44: 비상장 | Q44: - | R44: - | S44: - | T44: - | V44: - | W44: - | X44: - | Y44: - | Z44: -
...

Sheet 2(t-1)
A1: 종목명 | B1: 발행일 | C1: 일 | D1: 만기일 | E1: 일 | F1: 잔존일 | G1: 발행액(백만) | H1: 상장잔액(백만) | I1: 이자유형 | J1: 주기 | K1: 표면금리 | L1: 주식옵션 | M1: 중도상환 | N1: ABS | O1: 보증유형 | P1: 상장여부 | Q1: 공사모 | R1: 순위 | S1: 민평3사 | T1: 시가 | U1: C.가격 | V1: 신용그룹 | W1: 신용그룹코드 | X1: PPC100 | Y1: 듀레이션 | Z1: 표준코드
A2: 국민주택1종19-08-2 | B2: 43708 | C2: 토 | D2: 45535 | E2: 토 | F2: 0005-00-03 | G2: 944909 | H2: 944909 | I2: 복리 | J2: 12 | K2: 1 | L2: - | M2: - | N2: X | O2: 무보증 | P2: 상장 | Q2: 공모직접 | R2: 선 | S2: 1.277 | T2: 9862.69 | U2: 9863.83 | V2: 국민주택 1종 | W2: 1020000 | X2: 4.9485 | Y2: 5.0082 | Z2: KR101502D981*058
A3: 국민주택1종19-08 | B3: 43708 | C3: 토 | D3: 45535 | E3: 토 | F3: 0005-00-03 | G3: 493819 | H3: 493819 | I3: 복리 | J3: 12 | K3: 1.25 | L3: - | M3: - | N3: X | O3: 무보증 | P3: 상장 | Q3: 공모직접 | R3: 선 | S3: 1.277 | T3: 9984.68 | U3: 9985.84 | V3: 국민주택 1종 | W3: 1020000 | X3: 4.9485 | Y3: 5.0082 | Z3: KR101501D983*058
A4: 국민주택1종19-07-2 | B4: 43677 | C4: 수 | D4: 45504 | E4: 수 | F4: 0004-11-03 | G4: 430893 | H4: 430893 | I4: 복리 | J4: 12 | K4: 1.25 | L4: - | M4: - | N4: X | O4: 무보증 | P4: 상장 | Q4: 공모직접 | R4: 선 | S4: 1.278 | T4: 9995.06 | U4: 9987.02 | V4: 국민주택 1종 | W4: 1020000 | X4: 4.8654 | Y4: 4.9234 | Z4: KR101502D973*058
A5: 국민주택1종19-07 | B5: 43677 | C5: 수 | D5: 45504 | E5: 수 | F5: 0004-11-03 | G5: 1037399 | H5: 1037399 | I5: 복리 | J5: 12 | K5: 1.5 | L5: - | M5: - | N5: X | O5: 무보증 | P5: 상장 | Q5: 공모직접 | R5: 선 | S5: 1.278 | T5: 10119.05 | U5: 10109.14 | V5: 국민주택 1종 | W5: 1020000 | X5: 4.8654 | Y5: 4.9234 | Z5: KR101501D975*058
A6: 국민주택1종19-06-2 | B6: 43646 | C6: 일 | D6: 45473 | E6: 일 | F6: 0004-10-02 | G6: 1063638 | H6: 1063052 | I6: 복리 | J6: 12 | K6: 1.5 | L6: - | M6: - | N6: X | O6: 무보증 | P6: 상장 | Q6: 공모직접 | R6: 선 | S6: 1.275 | T6: 10131.02 | U6: 10108.29 | V6: 국민주택 1종 | W6: 1020000 | X6: 4.7826 | Y6: 4.8387 | Z6: KR101502D965*058
A7: 국민주택1종19-06 | B7: 43646 | C7: 일 | D7: 45473 | E7: 일 | F7: 0004-10-02 | G7: 79026 | H7: 78735 | I7: 복리 | J7: 12 | K7: 1.75 | L7: - | M7: - | N7: X | O7: 무보증 | P7: 상장 | Q7: 공모직접 | R7: 선 | S7: 1.275 | T7: 10257.05 | U7: 10230.36 | V7: 국민주택 1종 | W7: 1020000 | X7: 4.7826 | Y7: 4.8387 | Z7: KR101501D967*058
A8: 국민주택1종19-05 | B8: 43616 | C8: 금 | D8: 45443 | E8: 금 | F8: 0004-09-03 | G8: 1323766 | H8: 1322205 | I8: 복리 | J8: 12 | K8: 1.75 | L8: - | M8: - | N8: X | O8: 무보증 | P8: 상장 | Q8: 공모직접 | R8: 선 | S8: 1.274 | T8: 10268.15 | U8: 10226.69 | V8: 국민주택 1종 | W8: 1020000 | X8: 4.7022 | Y8: 4.7568 | Z8: KR101501D959*058
A9: 경기지역개발19-08 | B9: 43708 | C9: 토 | D9: 45535 | E9: 토 | F9: 0005-00-03 | G9: 24326 | H9: 24326 | I9: 복리 | J9: 12 | K9: 1.25 | L9: - | M9: - | N9: X | O9: 무보증 | P9: 상장 | Q9: 공모직접 | R9: 선 | S9: 1.327 | T9: 9960.46 | U9: 9961.19 | V9: 경기지방채 | W9: 2045000 | X9: 4.9461 | Y9: 5.0082 | Z9: KR2044012988*058
A10: 경기지역개발19-07 | B10: 43677 | C10: 수 | D10: 45504 | E10: 수 | F10: 0004-11-03 | G10: 29005 | H10: 29005 | I10: 복리 | J10: 12 | K10: 1.25 | L10: - | M10: - | N10: X | O10: 무보증 | P10: 상장 | Q10: 공모직접 | R10: 선 | S10: 1.326 | T10: 9972.02 | U10: 9962.75 | V10: 경기지방채 | W10: 2045000 | X10: 4.8631 | Y10: 4.9234 | Z10: KR2044012970*058
A11: 경기지역개발19-06 | B11: 43646 | C11: 일 | D11: 45473 | E11: 일 | F11: 0004-10-02 | G11: 24093 | H11: 24093 | I11: 복리 | J11: 12 | K11: 1.25 | L11: - | M11: - | N11: X | O11: 무보증 | P11: 상장 | Q11: 공모직접 | R11: 선 | S11: 1.324 | T11: 9983.73 | U11: 9964.23 | V11: 경기지방채 | W11: 2045000 | X11: 4.7803 | Y11: 4.8387 | Z11: KR2044012962*058
A12: 예보상환기금채2018-2 | B12: 43322 | C12: 금 | D12: 44418 | E12: 화 | F12: 0001-11-13 | G12: 800000 | H12: 800000 | I12: 이표고정 | J12: 6 | K12: 2.15 | L12: - | M12: - | N12: X | O12: 정부보증 | P12: 상장 | Q12: 공모직접 | R12: 선 | S12: 1.299 | T12: 10173.89 | U12: 10164.74 | V12: 정부보증채 | W12: 3030000 | X12: 1.9078 | Y12: 1.9193 | Z12: KR352601G881*058
A13: 예보상환기금채2018-1 | B13: 43131 | C13: 수 | D13: 44227 | E13: 일 | F13: 0001-05-03 | G13: 680000 | H13: 680000 | I13: 이표고정 | J13: 6 | K13: 2.52 | L13: - | M13: - | N13: X | O13: 정부보증 | P13: 상장 | Q13: 공모직접 | R13: 선 | S13: 1.279 | T13: 10193.6 | U13: 10175.05 | V13: 정부보증채 | W13: 3030000 | X13: 1.397 | Y13: 1.4089 | Z13: KR352601G816*058
... A15: 예보상환기금채2015-1 | B15: 42333 | C15: 수 | D15: 44160 | E15: 수 | F15: 0001-02-28 | G15: 880000 | H15: 880000 | I15: 이표고정 | J15: 6 | K15: 2.12 | L15: - | M15: - | N15: X | O15: 정부보증 | P15: 상장 | Q15: 공모직접 | R15: 선 | S15: 1.269 | T15: 10159.03 | U15: 10105.01 | V15: 정부보증채 | W15: 3030000 | X15: 1.2194 | Y15: 1.2282 | Z15: KR352601G5B1*058
A16: - | B16: - | D16: - | F16: - | G16: - | H16: - | I16: - | J16: - | K16: 1.34 | L16: - | M16: - | N16: X | O16: - | P16: 비상장 | Q16: - | R16: - | S16: - | T16: - | V16: - | W16: - | X16: - | Y16: - | Z16: -
A17: - | B17: - | D17: - | F17: - | G17: - | H17: - | I17: - | J17: - | K17: 1.61 | L17: - | M17: - | N17: X | O17: - | P17: 비상장 | Q17: - | R17: - | S17: - | T17: - | V17: - | W17: - | X17: - | Y17: - | Z17: -
A18: - | B18: - | D18: - | F18: - | G18: - | H18: - | I18: - | J18: - | K18: 2.84 | L18: - | M18: - | N18: X | O18: - | P18: 비상장 | Q18: - | R18: - | S18: - | T18: - | V18: - | W18: - | X18: - | Y18: - | Z18: -
A19: - | B19: - | D19: - | F19: - | G19: - | H19: - | I19: - | J19: - | K19: 2.98 | L19: - | M19: - | N19: X | O19: - | P19: 비상장 | Q19: - | R19: - | S19: - | T19: - | V19: - | W19: - | X19: - | Y19: - | Z19: -
A20: - | B20: - | D20: - | F20: - | G20: - | H20: - | I20: - | J20: - | K20: 2.98 | L20: - | M20: - | N20: X | O20: - | P20: 비상장 | Q20: - | R20: - | S20: - | T20: - | V20: - | W20: - | X20: - | Y20: - | Z20: -
A21: - | B21: - | D21: - | F21: - | G21: - | H21: - | I21: - | J21: - | K21: 3.12 | L21: - | M21: - | N21: X | O21: - | P21: 비상장 | Q21: - | R21: - | S21: - | T21: - | V21: - | W21: - | X21: - | Y21: - | Z21: -
A22: - | B22: - | D22: - | F22: - | G22: - | H22: - | I22: - | J22: - | K22: 2.74 | L22: - | M22: - | N22: X | O22: - | P22: 비상장 | Q22: - | R22: - | S22: - | T22: - | V22: - | W22: - | X22: - | Y22: - | Z22: -
A23: - | B23: - | D23: - | F23: - | G23: - | H23: - | I23: - | J23: - | K23: 3.67 | L23: - | M23: - | N23: X | O23: - | P23: 비상장 | Q23: - | R23: - | S23: - | T23: - | V23: - | W23: - | X23: - | Y23: - | Z23: -
A24: - | B24: - | D24: - | F24: - | G24: - | H24: - | I24: - | J24: - | K24: 3.04 | L24: - | M24: - | N24: X | O24: - | P24: 비상장 | Q24: - | R24: - | S24: - | T24: - | V24: - | W24: - | X24: - | Y24: - | Z24: -
A25: - | B25: - | D25: - | F25: - | G25: - | H25: - | I25: - | J25: - | K25: 3.07 | L25: - | M25: - | N25: X | O25: - | P25: 비상장 | Q25: - | R25: - | S25: - | T25: - | V25: - | W25: - | X25: - | Y25: - | Z25: -
A26: - | B26: - | D26: - | F26: - | G26: - | H26: - | I26: - | J26: - | K26: 4.14 | L26: - | M26: - | N26: X | O26: - | P26: 비상장 | Q26: - | R26: - | S26: - | T26: - | V26: - | W26: - | X26: - | Y26: - | Z26: -
A27: - | B27: - | D27: - | F27: - | G27: - | H27: - | I27: - | J27: - | K27: 3.88 | L27: - | M27: - | N27: X | O27: - | P27: 비상장 | Q27: - | R27: - | S27: - | T27: - | V27: - | W27: - | X27: - | Y27: - | Z27: -
A28: 예보기금특별계정채권2019-2 | B28: 43542 | C28: 월 | D28: 45369 | E28: 월 | F28: 0004-06-19 | G28: 360000 | H28: 360000 | I28: 이표고정 | J28: 6 | K28: 1.97 | L28: - | M28: - | N28: X | O28: 무보증 | P28: 상장 | Q28: 공모직접 | R28: 선 | S28: 1.331 | T28: 10368.83 | U28: 10282.48 | V28: 정부보증채 | W28: 3030000 | X28: 4.3207 | Y28: 4.3448 | Z28: KR352601G931*058
A29: 예보기금특별계정채권2019-1 | B29: 43479 | C29: 월 | D29: 45305 | E29: 일 | F29: 0004-04-17 | G29: 580000 | H29: 580000 | I29: 이표고정 | J29: 6 | K29: 1.98 | L29: - | M29: - | N29: X | O29: 무보증 | P29: 상장 | Q29: 공모직접 | R29: 선 | S29: 1.331 | T29: 10299.06 | U29: 10275.43 | V29: 정부보증채 | W29: 3030000 | X29: 4.1827 | Y29: 4.2101 | Z29: KR352601G915*058
A30: 예보기금특별계정채권2018-1 | B30: 43145 | C30: 수 | D30: 44971 | E30: 화 | F30: 0003-05-17 | G30: 320000 | H30: 320000 | I30: 이표고정 | J30: 6 | K30: 2.78 | L30: - | M30: - | N30: X | O30: 무보증 | P30: 상장 | Q30: 공모간접 | R30: 선 | S30: 1.33 | T30: 10499.42 | U30: 10490.36 | V30: 정부보증채 | W30: 3030000 | X30: 3.3045 | Y30: 3.3289 | Z30: KR352601G824*058
A31: 예보기금특별계정채권2017-4 | B31: 42970 | C31: 수 | D31: 44796 | E31: 화 | F31: 0002-11-26 | G31: 1200000 | H31: 1200000 | I31: 이표고정 | J31: 6 | K31: 2.2 | L31: - | M31: - | N31: X | O31: 무보증 | P31: 상장 | Q31: 공모간접 | R31: 선 | S31: 1.33 | T31: 10256.77 | U31: 10255.96 | V31: 정부보증채 | W31: 3030000 | X31: 2.8887 | Y31: 2.9072 | Z31: KR352601G782*058
A32: 예보기금특별계정채권2017-3 | B32: 42900 | C32: 수 | D32: 44726 | E32: 화 | F32: 0002-09-17 | G32: 900000 | H32: 900000 | I32: 이표고정 | J32: 6 | K32: 2.11 | L32: - | M32: - | N32: X | O32: 무보증 | P32: 상장 | Q32: 공모간접 | R32: 선 | S32: 1.329 | T32: 10256.59 | U32: 10214.84 | V32: 정부보증채 | W32: 3030000 | X32: 2.7022 | Y32: 2.7183 | Z32: KR352601G766*058
A33: 예보기금특별계정채권2015-1 | B33: 42025 | C33: 수 | D33: 44582 | E33: 금 | F33: 0002-04-24 | G33: 600000 | H33: 600000 | I33: 이표고정 | J33: 6 | K33: 2.34 | L33: - | M33: - | N33: X | O33: 무보증 | P33: 상장 | Q33: 공모직접 | R33: 선 | S33: 1.328 | T33: 10261.93 | U33: 10237.85 | V33: 정부보증채 | W33: 3030000 | X33: 2.3258 | Y33: 2.3435 | Z33: KR352601G519*058
A34: 예보기금특별계정채권2018-4 | B34: 43334 | C34: 수 | D34: 44430 | E34: 일 | F34: 0001-11-25 | G34: 450000 | H34: 450000 | I34: 이표고정 | J34: 6 | K34: 2.09 | L34: - | M34: - | N34: X | O34: 무보증 | P34: 상장 | Q34: 공모직접 | R34: 선 | S34: 1.33 | T34: 10151.62 | U34: 10149.47 | V34: 정부보증채 | W34: 3030000 | X34: 1.9405 | Y34: 1.953 | Z34: KR352602G889*058
A35: 예보기금특별계정채권2018-3 | B35: 43248 | C35: 월 | D35: 44344 | E35: 금 | F35: 0001-09-00 | G35: 400000 | H35: 400000 | I35: 이표고정 | J35: 6 | K35: 2.37 | L35: - | M35: - | N35: X | O35: 무보증 | P35: 상장 | Q35: 공모간접 | R35: 선 | S35: 1.321 | T35: 10239.91 | U35: 10181.94 | V35: 정부보증채 | W35: 3030000 | X35: 1.7052 | Y35: 1.7135 | Z35: KR352601G857*058
A36: 예보기금특별계정채권2017-2 | B36: 42872 | C36: 수 | D36: 44333 | E36: 월 | F36: 0001-08-19 | G36: 900000 | H36: 900000 | I36: 이표고정 | J36: 6 | K36: 1.99 | L36: - | M36: - | N36: X | O36: 무보증 | P36: 상장 | Q36: 공모간접 | R36: 선 | S36: 1.32 | T36: 10169.02 | U36: 10114.47 | V36: 정부보증채 | W36: 3030000 | X36: 1.6808 | Y36: 1.6887 | Z36: KR352601G758*058
A37: 예보기금특별계정채권2018-2 | B37: 43152 | C37: 수 | D37: 44248 | E37: 일 | F37: 0001-05-24 | G37: 280000 | H37: 280000 | I37: 이표고정 | J37: 6 | K37: 2.53 | L37: - | M37: - | N37: X | O37: 무보증 | P37: 상장 | Q37: 공모간접 | R37: 선 | S37: 1.314 | T37: 10182.55 | U37: 10178.04 | V37: 정부보증채 | W37: 3030000 | X37: 1.4531 | Y37: 1.4663 | Z37: KR352602G822*058
A38: 예보기금특별계정채권2017-1 | B38: 42753 | C38: 수 | D38: 44214 | E38: 월 | F38: 0001-04-21 | G38: 440000 | H38: 440000 | I38: 이표고정 | J38: 6 | K38: 1.88 | L38: - | M38: - | N38: X | O38: 무보증 | P38: 상장 | Q38: 공모간접 | R38: 선 | S38: 1.309 | T38: 10099.07 | U38: 10078.78 | V38: 정부보증채 | W38: 3030000 | X38: 1.3664 | Y38: 1.3778 | Z38: KR352601G717*058
A39: 예보기금특별계정채권2017-5 | B39: 43026 | C39: 수 | D39: 44122 | E39: 일 | F39: 0001-01-20 | G39: 290000 | H39: 290000 | I39: 이표고정 | J39: 6 | K39: 2.11 | L39: - | M39: - | N39: X | O39: 무보증 | P39: 상장 | Q39: 공모간접 | R39: 선 | S39: 1.299 | T39: 10167.37 | U39: 10092 | V39: 정부보증채 | W39: 3030000 | X39: 1.1172 | Y39: 1.1242 | Z39: KR352601G7A9*058
... A43: 예보기금특별계정채권2016-3 | B43: 42712 | C43: 목 | D43: 43807 | E43: 일 | F43: 0000-03-10 | G43: 600000 | H43: 600000 | I43: 이표고정 | J43: 6 | K43: 1.9 | L43: - | M43: - | N43: X | O43: 무보증 | P43: 상장 | Q43: 공모직접 | R43: 선 | S43: 1.343 | T43: 10057.34 | U43: 10015.51 | V43: 정부보증채 | W43: 3030000 | X43: 0.2776 | Y43: 0.2786 | Z43: KR352601G6C7*058
A44: - | B44: - | D44: - | F44: - | G44: - | H44: - | I44: - | J44: - | K44: 1.63 | L44: - | M44: - | N44: X | O44: - | P44: 비상장 | Q44: - | R44: - | S44: - | T44: - | V44: - | W44: - | X44: - | Y44: - | Z44: -
...

Sheet 시평
A1: 그룹명 | B1: 3M | C1: 6M | D1: 9M | E1: 1Y | F1: 1Y6M | G1: 2Y | H1: 2Y6M | I1: 3Y | J1: 4Y | K1: 5Y | L1: 7Y | M1: 10Y | N1: 15Y | O1: 20Y | P1: 30Y | Q1: 50Y
A2: 국고채 | B2: 1.245 | C2: 1.2 | D2: 1.156 | E2: 1.125 | F2: 1.156 | G2: 1.2 | H2: 1.201 | I2: 1.175 | J2: 1.213 | K2: 1.21 | L2: 1.235 | M2: 1.241 | N2: 1.244 | O2: 1.25 | P2: 1.25 | Q2: 1.27
A3: 국민주택1종 | B3: 1.257 | C3: 1.231 | D3: 1.202 | E3: 1.203 | F3: 1.228 | G3: 1.253 | H3: 1.253 | I3: 1.26 | J3: 1.262 | K3: 1.275 | L3: - | M3: - | N3: - | O3: - | P3: - | Q3: -
